Workbook
Name Lista_Aprueba: Parametros!$H$4:$H$30
Name Lista_Campana: Parametros!$D$4:$D$30
Name Lista_Cargo: Parametros!$E$4:$E$30
Name Lista_Estado: Parametros!$G$4:$G$29
Name Lista_Formador: Parametros!$F$4:$F$30

Sheet Registro
A1: No. | B1: CAMPAÑA | C1: FECHA DE INGRESO A FORMACIÓN | D1: CARGO | E1: No. DOCUMENTO | F1: NOMBRE COMPLETO | G1: CORREO ELECTRÓNICO | H1: TELÉFONO MÓVIL | I1: FORMADOR | J1: PRESENTACIÓN PERSONAL 5% | K1: PARTICIPACIÓN Y PUNTUALIDAD 10% | L1: EVALUACIÓN CONOCIMIENTO (DIA 2) 5% | M1: EVALUACIÓN TÉCNICA 10% | N1: SIMULACIÓN CON IA 20% | O1: EVALUACIÓN FINAL (CLÍNICA DE VENTAS) 50% | P1: NOTA FINAL | Q1: APRUEBA | R1: OBSERVACIONES | T1: AUX - ORDEN APROBADO (no borrar)
A2: =IF(F2="","",ROW()-1) -> 1 | B2: Posgrados | C2: 46204 | D2: Auxiliar gestor de vinculaciones | E2: 1193156026 | F2: Sara Isabel Molina Sánchez | G2: Molinasara453@gmail.com | H2: 3245742876 | I2: Todas | J2: 4 | K2: 5 | L2: 3 | M2: 4 | N2: 5 | O2: 3 | P2: =IF(F2="","",IF(COUNTIF(J2:O2,"D")>0,"",(IF(ISNUMBER(J2),J2,0)*Parametros!$K$4+IF(ISNUMBER(K2),K2,0)*Parametros!$K$5+IF(ISNUMBER(M2),M2,0)*Parametros!$K$6+IF(ISNUMBER(N2),N2,0)*Parametros!$K$7+IF(ISNUMBER(O2),O2,0)*Parametros!$K$8)/Parametros!$B$2)) -> 72 | Q2: =IF(F2="","",IF(COUNTIF(J2:O2,"D")>0,"Desiste",IF(IFERROR(P2,0)>=Parametros!$B$1,"Aprueba","No aprueba"))) -> Aprueba | T2: =IF($Q2="Aprueba",COUNTIF($Q$2:$Q2,"Aprueba"),"") -> 1
A3: =IF(F3="","",ROW()-1) -> 2 | B3: Posgrados | C3: 46204 | D3: Auxiliar gestor de vinculaciones | E3: 1022988349 | F3: Michelle Geraldine Bejarano Torres | G3: michelletorres2593@hotmail.com | H3: 3123702518 | I3: Todas | J3: 4 | K3: 2 | L3: 3 | M3: 4 | N3: 4 | O3: 3 | P3: =IF(F3="","",IF(COUNTIF(J3:O3,"D")>0,"",(IF(ISNUMBER(J3),J3,0)*Parametros!$K$4+IF(ISNUMBER(K3),K3,0)*Parametros!$K$5+IF(ISNUMBER(M3),M3,0)*Parametros!$K$6+IF(ISNUMBER(N3),N3,0)*Parametros!$K$7+IF(ISNUMBER(O3),O3,0)*Parametros!$K$8)/Parametros!$B$2)) -> 62 | Q3: =IF(F3="","",IF(COUNTIF(J3:O3,"D")>0,"Desiste",IF(IFERROR(P3,0)>=Parametros!$B$1,"Aprueba","No aprueba"))) -> No aprueba | T3: =IF($Q3="Aprueba",COUNTIF($Q$2:$Q3,"Aprueba"),"")
A4: =IF(F4="","",ROW()-1) -> 3 | B4: Posgrados | C4: 46204 | D4: Auxiliar gestor de vinculaciones | E4: 1016001652 | F4: Helen Sofia Calderon Camelo | G4: helencalderon910@gmail.com | H4: ‪3239227093‬ | I4: Todas | J4: 4 | K4: 4 | L4: 3 | M4: 4 | N4: 5 | O4: 3 | P4: =IF(F4="","",IF(COUNTIF(J4:O4,"D")>0,"",(IF(ISNUMBER(J4),J4,0)*Parametros!$K$4+IF(ISNUMBER(K4),K4,0)*Parametros!$K$5+IF(ISNUMBER(M4),M4,0)*Parametros!$K$6+IF(ISNUMBER(N4),N4,0)*Parametros!$K$7+IF(ISNUMBER(O4),O4,0)*Parametros!$K$8)/Parametros!$B$2)) -> 70 | Q4: =IF(F4="","",IF(COUNTIF(J4:O4,"D")>0,"Desiste",IF(IFERROR(P4,0)>=Parametros!$B$1,"Aprueba","No aprueba"))) -> Aprueba | T4: =IF($Q4="Aprueba",COUNTIF($Q$2:$Q4,"Aprueba"),"") -> 2
A5: =IF(F5="","",ROW()-1) -> 4 | B5: Posgrados | C5: 46204 | D5: Auxiliar gestor de vinculaciones | E5: 1012385263 | F5: Cindy Paola Cuellar Montoya | G5: Cindypaolacuellar@gmail.com | H5: 3172616867 | I5: Todas | J5: 3 | K5: 3 | L5: 3 | M5: 3 | N5: 5 | O5: 3 | P5: =IF(F5="","",IF(COUNTIF(J5:O5,"D")>0,"",(IF(ISNUMBER(J5),J5,0)*Parametros!$K$4+IF(ISNUMBER(K5),K5,0)*Parametros!$K$5+IF(ISNUMBER(M5),M5,0)*Parametros!$K$6+IF(ISNUMBER(N5),N5,0)*Parametros!$K$7+IF(ISNUMBER(O5),O5,0)*Parametros!$K$8)/Parametros!$B$2)) -> 65 | Q5: =IF(F5="","",IF(COUNTIF(J5:O5,"D")>0,"Desiste",IF(IFERROR(P5,0)>=Parametros!$B$1,"Aprueba","No aprueba"))) -> No aprueba | R5: Llega tarde | T5: =IF($Q5="Aprueba",COUNTIF($Q$2:$Q5,"Aprueba"),"")
A6: =IF(F6="","",ROW()-1) -> 5 | B6: Posgrados | C6: 46204 | D6: Auxiliar gestor de vinculaciones | E6: 1001314657 | F6: Thomas Bernardo Fernandez Laverde | G6: tfernandezlaverde@gmail.com | H6: 3103798566 | I6: Todas | J6: 4 | K6: 5 | L6: 3 | M6: 4 | N6: 5 | O6: 3 | P6: =IF(F6="","",IF(COUNTIF(J6:O6,"D")>0,"",(IF(ISNUMBER(J6),J6,0)*Parametros!$K$4+IF(ISNUMBER(K6),K6,0)*Parametros!$K$5+IF(ISNUMBER(M6),M6,0)*Parametros!$K$6+IF(ISNUMBER(N6),N6,0)*Parametros!$K$7+IF(ISNUMBER(O6),O6,0)*Parametros!$K$8)/Parametros!$B$2)) -> 72 | Q6: =IF(F6="","",IF(COUNTIF(J6:O6,"D")>0,"Desiste",IF(IFERROR(P6,0)>=Parametros!$B$1,"Aprueba","No aprueba"))) -> Aprueba | T6: =IF($Q6="Aprueba",COUNTIF($Q$2:$Q6,"Aprueba"),"") -> 3
A7: =IF(F7="","",ROW()-1) -> 6 | B7: Posgrados | C7: 46204 | D7: Auxiliar gestor de vinculaciones | E7: 52956322 | F7: Julie Caterine Villalobos Ortiz | G7: Juliecaterine23@gmail.com | H7: 3213264788 | I7: Todas | J7: 5 | K7: 5 | L7: 3 | M7: 4 | N7: 4 | O7: 3 | P7: =IF(F7="","",IF(COUNTIF(J7:O7,"D")>0,"",(IF(ISNUMBER(J7),J7,0)*Parametros!$K$4+IF(ISNUMBER(K7),K7,0)*Parametros!$K$5+IF(ISNUMBER(M7),M7,0)*Parametros!$K$6+IF(ISNUMBER(N7),N7,0)*Parametros!$K$7+IF(ISNUMBER(O7),O7,0)*Parametros!$K$8)/Parametros!$B$2)) -> 69 | Q7: =IF(F7="","",IF(COUNTIF(J7:O7,"D")>0,"Desiste",IF(IFERROR(P7,0)>=Parametros!$B$1,"Aprueba","No aprueba"))) -> No aprueba | T7: =IF($Q7="Aprueba",COUNTIF($Q$2:$Q7,"Aprueba"),"")
A8: =IF(F8="","",ROW()-1) -> 7 | B8: Posgrados | C8: 46204 | D8: Auxiliar gestor de vinculaciones | E8: 10191156098 | F8: Yaricet Bricet Cárcamo Morales | G8: Yaricetbricet@gmail.com | H8: 3008533917 | I8: Todas | J8: 4 | K8: 4 | L8: 3 | M8: 4 | N8: 3 | O8: 3 | P8: =IF(F8="","",IF(COUNTIF(J8:O8,"D")>0,"",(IF(ISNUMBER(J8),J8,0)*Parametros!$K$4+IF(ISNUMBER(K8),K8,0)*Parametros!$K$5+IF(ISNUMBER(M8),M8,0)*Parametros!$K$6+IF(ISNUMBER(N8),N8,0)*Parametros!$K$7+IF(ISNUMBER(O8),O8,0)*Parametros!$K$8)/Parametros!$B$2)) -> 62 | Q8: =IF(F8="","",IF(COUNTIF(J8:O8,"D")>0,"Desiste",IF(IFERROR(P8,0)>=Parametros!$B$1,"Aprueba","No aprueba"))) -> No aprueba | T8: =IF($Q8="Aprueba",COUNTIF($Q$2:$Q8,"Aprueba"),"")
A9: =IF(F9="","",ROW()-1) -> 8 | B9: Posgrados | C9: 46204 | D9: Auxiliar gestor de vinculaciones | E9: 1033096735 | F9: Pablo Steven Ochoa Rodriguez | G9: Pablorodriguez8q@gmail.com | H9: 3196588439 | I9: Todas | J9: 3 | K9: 4 | L9: 3 | M9: 5 | N9: 5 | O9: 4 | P9: =IF(F9="","",IF(COUNTIF(J9:O9,"D")>0,"",(IF(ISNUMBER(J9),J9,0)*Parametros!$K$4+IF(ISNUMBER(K9),K9,0)*Parametros!$K$5+IF(ISNUMBER(M9),M9,0)*Parametros!$K$6+IF(ISNUMBER(N9),N9,0)*Parametros!$K$7+IF(ISNUMBER(O9),O9,0)*Parametros!$K$8)/Parametros!$B$2)) -> 81 | Q9: =IF(F9="","",IF(COUNTIF(J9:O9,"D")>0,"Desiste",IF(IFERROR(P9,0)>=Parametros!$B$1,"Aprueba","No aprueba"))) -> Aprueba | T9: =IF($Q9="Aprueba",COUNTIF($Q$2:$Q9,"Aprueba"),"") -> 4
A10: =IF(F10="","",ROW()-1) -> 9 | B10: Posgrados | C10: 46204 | D10: Auxiliar gestor de vinculaciones | E10: 1000219286 | F10: Lucia Fernanda Cruz Canchila | G10: Luciacruz0414@gmail.com | H10: 3005145730 | I10: Todas | J10: 4 | K10: 2 | L10: 3 | M10: 5 | N10: 5 | O10: 3 | P10: =IF(F10="","",IF(COUNTIF(J10:O10,"D")>0,"",(IF(ISNUMBER(J10),J10,0)*Parametros!$K$4+IF(ISNUMBER(K10),K10,0)*Parametros!$K$5+IF(ISNUMBER(M10),M10,0)*Parametros!$K$6+IF(ISNUMBER(N10),N10,0)*Parametros!$K$7+IF(ISNUMBER(O10),O10,0)*Parametros!$K$8)/Parametros!$B$2)) -> 68 | Q10: =IF(F10="","",IF(COUNTIF(J10:O10,"D")>0,"Desiste",IF(IFERROR(P10,0)>=Parametros!$B$1,"Aprueba","No aprueba"))) -> No aprueba | R10: Llega tarde | T10: =IF($Q10="Aprueba",COUNTIF($Q$2:$Q10,"Aprueba"),"")
A11: =IF(F11="","",ROW()-1) -> 10 | B11: Posgrados | C11: 46204 | D11: Auxiliar gestor de vinculaciones | E11: 1004961429 | F11: Jhon Stiven Marin Valencia | G11: jhonstivenmarin02@gmail.com | H11: 3219466413 | I11: Todas | J11: 3 | K11: 3 | L11: 3 | M11: 4 | N11: 4 | O11: 4 | P11: =IF(F11="","",IF(COUNTIF(J11:O11,"D")>0,"",(IF(ISNUMBER(J11),J11,0)*Parametros!$K$4+IF(ISNUMBER(K11),K11,0)*Parametros!$K$5+IF(ISNUMBER(M11),M11,0)*Parametros!$K$6+IF(ISNUMBER(N11),N11,0)*Parametros!$K$7+IF(ISNUMBER(O11),O11,0)*Parametros!$K$8)/Parametros!$B$2)) -> 73 | Q11: =IF(F11="","",IF(COUNTIF(J11:O11,"D")>0,"Desiste",IF(IFERROR(P11,0)>=Parametros!$B$1,"Aprueba","No aprueba"))) -> Aprueba | R11: Llega tarde | T11: =IF($Q11="Aprueba",COUNTIF($Q$2:$Q11,"Aprueba"),"") -> 5
A12: =IF(F12="","",ROW()-1) -> 11 | B12: Posgrados | C12: 46204 | D12: Auxiliar gestor de vinculaciones | E12: 53121281 | F12: Yulieth Paola Rodriguez Cañon | G12: ypaolarodriguez14@gmail.com | H12: 3112142736 | I12: Todas | J12: 4 | K12: 4 | L12: 3 | M12: 3 | N12: 5 | O12: 4 | P12: =IF(F12="","",IF(COUNTIF(J12:O12,"D")>0,"",(IF(ISNUMBER(J12),J12,0)*Parametros!$K$4+IF(ISNUMBER(K12),K12,0)*Parametros!$K$5+IF(ISNUMBER(M12),M12,0)*Parametros!$K$6+IF(ISNUMBER(N12),N12,0)*Parametros!$K$7+IF(ISNUMBER(O12),O12,0)*Parametros!$K$8)/Parametros!$B$2)) -> 78 | Q12: =IF(F12="","",IF(COUNTIF(J12:O12,"D")>0,"Desiste",IF(IFERROR(P12,0)>=Parametros!$B$1,"Aprueba","No aprueba"))) -> Aprueba | T12: =IF($Q12="Aprueba",COUNTIF($Q$2:$Q12,"Aprueba"),"") -> 6
A13: =IF(F13="","",ROW()-1) -> 12 | B13: Posgrados | C13: 46204 | D13: Auxiliar gestor de vinculaciones | E13: 1019138287 | F13: Natalia Fernanda Mendieta Oicata | G13: nataliamendieta2025@gmail.com | H13: 3003020830 | I13: Todas | J13: 5 | K13: 5 | L13: 3 | M13: 3 | N13: 4 | O13: 3 | P13: =IF(F13="","",IF(COUNTIF(J13:O13,"D")>0,"",(IF(ISNUMBER(J13),J13,0)*Parametros!$K$4+IF(ISNUMBER(K13),K13,0)*Parametros!$K$5+IF(ISNUMBER(M13),M13,0)*Parametros!$K$6+IF(ISNUMBER(N13),N13,0)*Parametros!$K$7+IF(ISNUMBER(O13),O13,0)*Parametros!$K$8)/Parametros!$B$2)) -> 67 | Q13: =IF(F13="","",IF(COUNTIF(J13:O13,"D")>0,"Desiste",IF(IFERROR(P13,0)>=Parametros!$B$1,"Aprueba","No aprueba"))) -> No aprueba | T13: =IF($Q13="Aprueba",COUNTIF($Q$2:$Q13,"Aprueba"),"")
A14: =IF(F14="","",ROW()-1) -> 13 | B14: Posgrados | C14: 46211 | D14: Auxiliar gestor de vinculaciones | E14: 1019145849 | F14: Jhonatan David Londoño Baldovino | G14: Jdlbaldovino199@gmail.com | H14: 3208836403 | I14: Todas | J14: 4 | K14: 4 | L14: 3 | M14: 3 | N14: 3 | O14: 2 | P14: =IF(F14="","",IF(COUNTIF(J14:O14,"D")>0,"",(IF(ISNUMBER(J14),J14,0)*Parametros!$K$4+IF(ISNUMBER(K14),K14,0)*Parametros!$K$5+IF(ISNUMBER(L14),L14,0)*Parametros!$K$6+IF(ISNUMBER(M14),M14,0)*Parametros!$K$7+IF(ISNUMBER(N14),N14,0)*Parametros!$K$8+IF(ISNUMBER(O14),O14,0)*Parametros!$K$9)/Parametros!$B$2)) -> 62 | Q14: =IF(F14="","",IF(COUNTIF(J14:O14,"D")>0,"Desiste",IF(IFERROR(P14,0)>=Parametros!$B$1,"Aprueba","No aprueba"))) -> No aprueba | T14: =IF($Q14="Aprueba",COUNTIF($Q$2:$Q14,"Aprueba"),"")
A15: =IF(F15="","",ROW()-1) -> 14 | B15: Posgrados | C15: 46211 | D15: Auxiliar gestor de vinculaciones | E15: 1001056884 | F15: David Felipe Hernández Hernández | G15: david.hernandez.dtk@gmail.com | H15: 3028250517 | I15: Todas | J15: 4 | K15: 4 | L15: 3 | M15: 3 | N15: 3 | O15: 3 | P15: =IF(F15="","",IF(COUNTIF(J15:O15,"D")>0,"",(IF(ISNUMBER(J15),J15,0)*Parametros!$K$4+IF(ISNUMBER(K15),K15,0)*Parametros!$K$5+IF(ISNUMBER(L15),L15,0)*Parametros!$K$6+IF(ISNUMBER(M15),M15,0)*Parametros!$K$7+IF(ISNUMBER(N15),N15,0)*Parametros!$K$8+IF(ISNUMBER(O15),O15,0)*Parametros!$K$9)/Parametros!$B$2)) -> 63 | Q15: =IF(F15="","",IF(COUNTIF(J15:O15,"D")>0,"Desiste",IF(IFERROR(P15,0)>=Parametros!$B$1,"Aprueba","No aprueba"))) -> No aprueba | T15: =IF($Q15="Aprueba",COUNTIF($Q$2:$Q15,"Aprueba"),"")
A16: =IF(F16="","",ROW()-1) -> 15 | B16: Posgrados | C16: 46211 | D16: Auxiliar gestor de vinculaciones | E16: 1024585365 | F16: Cristian David Celis Garcia | G16: cristianceliss9719@gmail.com | H16: 3216686201 | I16: Todas | J16: 4 | K16: 4 | L16: 3 | M16: 3 | N16: 4 | O16: 3 | P16: =IF(F16="","",IF(COUNTIF(J16:O16,"D")>0,"",(IF(ISNUMBER(J16),J16,0)*Parametros!$K$4+IF(ISNUMBER(K16),K16,0)*Parametros!$K$5+IF(ISNUMBER(L16),L16,0)*Parametros!$K$6+IF(ISNUMBER(M16),M16,0)*Parametros!$K$7+IF(ISNUMBER(N16),N16,0)*Parametros!$K$8+IF(ISNUMBER(O16),O16,0)*Parametros!$K$9)/Parametros!$B$2)) -> 73 | Q16: =IF(F16="","",IF(COUNTIF(J16:O16,"D")>0,"Desiste",IF(IFERROR(P16,0)>=Parametros!$B$1,"Aprueba","No aprueba"))) -> Aprueba | R16: Llega tarde | T16: =IF($Q16="Aprueba",COUNTIF($Q$2:$Q16,"Aprueba"),"") -> 7
A17: =IF(F17="","",ROW()-1) -> 16 | B17: Posgrados | C17: 46211 | D17: Auxiliar gestor de vinculaciones | E17: 1000547797 | F17: Kamy Lizeth Rios Gomez | G17: riosgomezkamy@gmail.com | H17: 3112534635 | I17: Todas | J17: 5 | K17: 4 | L17: 2 | M17: 5 | N17: 5 | O17: 3 | P17: =IF(F17="","",IF(COUNTIF(J17:O17,"D")>0,"",(IF(ISNUMBER(J17),J17,0)*Parametros!$K$4+IF(ISNUMBER(K17),K17,0)*Parametros!$K$5+IF(ISNUMBER(L17),L17,0)*Parametros!$K$6+IF(ISNUMBER(M17),M17,0)*Parametros!$K$7+IF(ISNUMBER(N17),N17,0)*Parametros!$K$8+IF(ISNUMBER(O17),O17,0)*Parametros!$K$9)/Parametros!$B$2)) -> 90 | Q17: =IF(F17="","",IF(COUNTIF(J17:O17,"D")>0,"Desiste",IF(IFERROR(P17,0)>=Parametros!$B$1,"Aprueba","No aprueba"))) -> Aprueba | T17: =IF($Q17="Aprueba",COUNTIF($Q$2:$Q17,"Aprueba"),"") -> 8
A18: =IF(F18="","",ROW()-1) -> 17 | B18: Posgrados | C18: 46211 | D18: Auxiliar gestor de vinculaciones | E18: 1023867138 | F18: Yisell Dayana Castro González | G18: Gonzalezdayanna730@gmail.com | H18: 3143600585 | I18: Todas | J18: 4 | K18: 4 | L18: 3 | M18: 3 | N18: 4 | O18: 2 | P18: =IF(F18="","",IF(COUNTIF(J18:O18,"D")>0,"",(IF(ISNUMBER(J18),J18,0)*Parametros!$K$4+IF(ISNUMBER(K18),K18,0)*Parametros!$K$5+IF(ISNUMBER(L18),L18,0)*Parametros!$K$6+IF(ISNUMBER(M18),M18,0)*Parametros!$K$7+IF(ISNUMBER(N18),N18,0)*Parametros!$K$8+IF(ISNUMBER(O18),O18,0)*Parametros!$K$9)/Parametros!$B$2)) -> 72 | Q18: =IF(F18="","",IF(COUNTIF(J18:O18,"D")>0,"Desiste",IF(IFERROR(P18,0)>=Parametros!$B$1,"Aprueba","No aprueba"))) -> Aprueba | T18: =IF($Q18="Aprueba",COUNTIF($Q$2:$Q18,"Aprueba"),"") -> 9
A19: =IF(F19="","",ROW()-1) -> 18 | B19: Posgrados | C19: 46211 | D19: Auxiliar gestor de vinculaciones | E19: 1000810776 | F19: Nataly Andrea Maecha Lizarazo | G19: natamahecha23@gmail.com | H19: 3204984051 | I19: Todas | J19: 4 | K19: 4 | L19: 2 | M19: 4 | N19: 4 | O19: 2 | P19: =IF(F19="","",IF(COUNTIF(J19:O19,"D")>0,"",(IF(ISNUMBER(J19),J19,0)*Parametros!$K$4+IF(ISNUMBER(K19),K19,0)*Parametros!$K$5+IF(ISNUMBER(L19),L19,0)*Parametros!$K$6+IF(ISNUMBER(M19),M19,0)*Parametros!$K$7+IF(ISNUMBER(N19),N19,0)*Parametros!$K$8+IF(ISNUMBER(O19),O19,0)*Parametros!$K$9)/Parametros!$B$2)) -> 74 | Q19: =IF(F19="","",IF(COUNTIF(J19:O19,"D")>0,"Desiste",IF(IFERROR(P19,0)>=Parametros!$B$1,"Aprueba","No aprueba"))) -> Aprueba | T19: =IF($Q19="Aprueba",COUNTIF($Q$2:$Q19,"Aprueba"),"") -> 10
A20: =IF(F20="","",ROW()-1) -> 19 | B20: Posgrados | C20: 46211 | D20: Auxiliar gestor de vinculaciones | E20: 1001271946 | F20: Luisa Fernanda Rodríguez Sarmiento | G20: feryantonella13@gmail.com | H20: 3054399778 | I20: Todas | J20: 3 | K20: 5 | L20: 3 | M20: 3 | N20: 4 | O20: 3 | P20: =IF(F20="","",IF(COUNTIF(J20:O20,"D")>0,"",(IF(ISNUMBER(J20),J20,0)*Parametros!$K$4+IF(ISNUMBER(K20),K20,0)*Parametros!$K$5+IF(ISNUMBER(L20),L20,0)*Parametros!$K$6+IF(ISNUMBER(M20),M20,0)*Parametros!$K$7+IF(ISNUMBER(N20),N20,0)*Parametros!$K$8+IF(ISNUMBER(O20),O20,0)*Parametros!$K$9)/Parametros!$B$2)) -> 74 | Q20: =IF(F20="","",IF(COUNTIF(J20:O20,"D")>0,"Desiste",IF(IFERROR(P20,0)>=Parametros!$B$1,"Aprueba","No aprueba"))) -> Aprueba | R20: Presentación personal | T20: =IF($Q20="Aprueba",COUNTIF($Q$2:$Q20,"Aprueba"),"") -> 11
A21: =IF(F21="","",ROW()-1) -> 20 | B21: Posgrados | C21: 46211 | D21: Auxiliar gestor de vinculaciones | E21: 1117813165 | F21: Yedinson Stiven Ramirez Perdómo | G21: kramirezperdomo@gmail.com | H21: 3506517824 | I21: Todas | J21: 5 | K21: 5 | L21: 3 | M21: 5 | N21: 5 | O21: 3 | P21: =IF(F21="","",IF(COUNTIF(J21:O21,"D")>0,"",(IF(ISNUMBER(J21),J21,0)*Parametros!$K$4+IF(ISNUMBER(K21),K21,0)*Parametros!$K$5+IF(ISNUMBER(L21),L21,0)*Parametros!$K$6+IF(ISNUMBER(M21),M21,0)*Parametros!$K$7+IF(ISNUMBER(N21),N21,0)*Parametros!$K$8+IF(ISNUMBER(O21),O21,0)*Parametros!$K$9)/Parametros!$B$2)) -> 94 | Q21: =IF(F21="","",IF(COUNTIF(J21:O21,"D")>0,"Desiste",IF(IFERROR(P21,0)>=Parametros!$B$1,"Aprueba","No aprueba"))) -> Aprueba | T21: =IF($Q21="Aprueba",COUNTIF($Q$2:$Q21,"Aprueba"),"") -> 12
A22: =IF(F22="","",ROW()-1) -> 21 | B22: Posgrados | C22: 46211 | D22: Auxiliar gestor de vinculaciones | E22: 1045686807 | F22: Gisell Del Carmen Cabrera Maldonado | G22: cgisell890@gmail.com | H22: 3017718956 | I22: Todas | J22: 4 | K22: 3 | L22: 5 | M22: 4 | N22: 2 | O22: 2 | P22: =IF(F22="","",IF(COUNTIF(J22:O22,"D")>0,"",(IF(ISNUMBER(J22),J22,0)*Parametros!$K$4+IF(ISNUMBER(K22),K22,0)*Parametros!$K$5+IF(ISNUMBER(L22),L22,0)*Parametros!$K$6+IF(ISNUMBER(M22),M22,0)*Parametros!$K$7+IF(ISNUMBER(N22),N22,0)*Parametros!$K$8+IF(ISNUMBER(O22),O22,0)*Parametros!$K$9)/Parametros!$B$2)) -> 58 | Q22: =IF(F22="","",IF(COUNTIF(J22:O22,"D")>0,"Desiste",IF(IFERROR(P22,0)>=Parametros!$B$1,"Aprueba","No aprueba"))) -> No aprueba | R22: Actitud | T22: =IF($Q22="Aprueba",COUNTIF($Q$2:$Q22,"Aprueba"),"")
A23: =IF(F23="","",ROW()-1) -> 22 | B23: Posgrados | C23: 46211 | D23: Auxiliar gestor de vinculaciones | E23: 1070595836 | F23: Hebert Julián Casilimas Ricardo | G23: julian180703@icloud.com | H23: 3229087879 | I23: Todas | J23: 4 | K23: 4 | L23: 3 | M23: 5 | N23: 5 | O23: 3 | P23: =IF(F23="","",IF(COUNTIF(J23:O23,"D")>0,"",(IF(ISNUMBER(J23),J23,0)*Parametros!$K$4+IF(ISNUMBER(K23),K23,0)*Parametros!$K$5+IF(ISNUMBER(L23),L23,0)*Parametros!$K$6+IF(ISNUMBER(M23),M23,0)*Parametros!$K$7+IF(ISNUMBER(N23),N23,0)*Parametros!$K$8+IF(ISNUMBER(O23),O23,0)*Parametros!$K$9)/Parametros!$B$2)) -> 91 | Q23: =IF(F23="","",IF(COUNTIF(J23:O23,"D")>0,"Desiste",IF(IFERROR(P23,0)>=Parametros!$B$1,"Aprueba","No aprueba"))) -> Aprueba | T23: =IF($Q23="Aprueba",COUNTIF($Q$2:$Q23,"Aprueba"),"") -> 13
A24: =IF(F24="","",ROW()-1) -> 23 | B24: Posgrados | C24: 46211 | D24: Auxiliar gestor de vinculaciones | E24: 1140850536 | F24: Nelvis Mirleth Gutiérrez Orozco | G24: Milrthgutierrez@gmail.com | H24: 3028092333 | I24: Todas | J24: 3 | K24: 3 | L24: 2 | M24: 3 | N24: 3 | O24: 1 | P24: =IF(F24="","",IF(COUNTIF(J24:O24,"D")>0,"",(IF(ISNUMBER(J24),J24,0)*Parametros!$K$4+IF(ISNUMBER(K24),K24,0)*Parametros!$K$5+IF(ISNUMBER(L24),L24,0)*Parametros!$K$6+IF(ISNUMBER(M24),M24,0)*Parametros!$K$7+IF(ISNUMBER(N24),N24,0)*Parametros!$K$8+IF(ISNUMBER(O24),O24,0)*Parametros!$K$9)/Parametros!$B$2)) -> 56 | Q24: =IF(F24="","",IF(COUNTIF(J24:O24,"D")>0,"Desiste",IF(IFERROR(P24,0)>=Parametros!$B$1,"Aprueba","No aprueba"))) -> No aprueba | R24: Actitud | T24: =IF($Q24="Aprueba",COUNTIF($Q$2:$Q24,"Aprueba"),"")
A25: =IF(F25="","",ROW()-1) -> 24 | B25: Posgrados | C25: 46211 | D25: Auxiliar gestor de vinculaciones | E25: 1073709574 | F25: Johan Sebastian Peña Ramos | G25: seebastian0118@gmail.com | H25: 3138749486 | I25: Todas | J25: 4 | K25: 4 | L25: 3 | M25: 3 | N25: 2 | O25: 4 | P25: =IF(F25="","",IF(COUNTIF(J25:O25,"D")>0,"",(IF(ISNUMBER(J25),J25,0)*Parametros!$K$4+IF(ISNUMBER(K25),K25,0)*Parametros!$K$5+IF(ISNUMBER(L25),L25,0)*Parametros!$K$6+IF(ISNUMBER(M25),M25,0)*Parametros!$K$7+IF(ISNUMBER(N25),N25,0)*Parametros!$K$8+IF(ISNUMBER(O25),O25,0)*Parametros!$K$9)/Parametros!$B$2)) -> 54 | Q25: =IF(F25="","",IF(COUNTIF(J25:O25,"D")>0,"Desiste",IF(IFERROR(P25,0)>=Parametros!$B$1,"Aprueba","No aprueba"))) -> No aprueba | T25: =IF($Q25="Aprueba",COUNTIF($Q$2:$Q25,"Aprueba"),"")
A26: =IF(F26="","",ROW()-1) -> 25 | B26: Pregrado Virtual | C26: 46224 | D26: Auxiliar gestor de vinculaciones | E26: 1001187759 | F26: Julian David Jiménez Moreno | G26: Julian.david.jimenez.moreno@gmail.com | H26: 3124832044 | I26: Karen Margarita Puerta | J26: 4 | K26: 4 | L26: 3 | M26: 3 | N26: 5 | O26: 4 | P26: 4 | Q26: =IF(F26="","",IF(COUNTIF(J26:O26,"D")>0,"Desiste",IF(IFERROR(P26,0)>=Parametros!$B$1,"Aprueba","No aprueba"))) -> No aprueba | T26: =IF($Q26="Aprueba",COUNTIF($Q$2:$Q26,"Aprueba"),"")
A27: =IF(F27="","",ROW()-1) -> 26 | B27: Pregrado Virtual | C27: 46224 | D27: Auxiliar gestor de vinculaciones | E27: 1012455544 | F27: Claudia Yadira Suta Torres | G27: claudiasuta029@gmail.com | H27: 3227861878 | I27: Karen Margarita Puerta | J27: 4 | K27: 3 | L27: 3 | M27: 4 | N27: 4 | O27: 4 | P27: =IF(F27="","",IF(COUNTIF(J27:O27,"D")>0,"",(IF(ISNUMBER(J27),J27,0)*Parametros!$K$4+IF(ISNUMBER(K27),K27,0)*Parametros!$K$5+IF(ISNUMBER(M27),M27,0)*Parametros!$K$6+IF(ISNUMBER(N27),N27,0)*Parametros!$K$7+IF(ISNUMBER(O27),O27,0)*Parametros!$K$8)/Parametros!$B$2)) -> 74 | Q27: =IF(F27="","",IF(COUNTIF(J27:O27,"D")>0,"Desiste",IF(IFERROR(P27,0)>=Parametros!$B$1,"Aprueba","No aprueba"))) -> Aprueba | T27: =IF($Q27="Aprueba",COUNTIF($Q$2:$Q27,"Aprueba"),"") -> 14
A28: =IF(F28="","",ROW()-1) -> 27 | B28: Pregrado Virtual | C28: 46224 | D28: Auxiliar gestor de vinculaciones | E28: 1001056755 | F28: Cristian Manuel Jiménez Gómez | G28: jimenezsc07@gmail.com | H28: 3123926446 | I28: Karen Margarita Puerta | J28: 3 | K28: 3 | L28: 2 | M28: 2 | N28: 4 | O28: 3 | P28: =IF(F28="","",IF(COUNTIF(J28:O28,"D")>0,"",(IF(ISNUMBER(J28),J28,0)*Parametros!$K$4+IF(ISNUMBER(K28),K28,0)*Parametros!$K$5+IF(ISNUMBER(M28),M28,0)*Parametros!$K$6+IF(ISNUMBER(N28),N28,0)*Parametros!$K$7+IF(ISNUMBER(O28),O28,0)*Parametros!$K$8)/Parametros!$B$2)) -> 59 | Q28: =IF(F28="","",IF(COUNTIF(J28:O28,"D")>0,"Desiste",IF(IFERROR(P28,0)>=Parametros!$B$1,"Aprueba","No aprueba"))) -> No aprueba | T28: =IF($Q28="Aprueba",COUNTIF($Q$2:$Q28,"Aprueba"),"")
A29: =IF(F29="","",ROW()-1) -> 28 | B29: Pregrado Virtual | C29: 46224 | D29: Auxiliar gestor de vinculaciones | E29: 1000328420 | F29: Miguel Ángel Becerra Garcia | G29: Saclaro920@gmail.com | H29: 3223167270 | I29: Karen Margarita Puerta | J29: 3 | K29: 3 | L29: 4 | M29: 3 | N29: 5 | O29: 2 | P29: =IF(F29="","",IF(COUNTIF(J29:O29,"D")>0,"",(IF(ISNUMBER(J29),J29,0)*Parametros!$K$4+IF(ISNUMBER(K29),K29,0)*Parametros!$K$5+IF(ISNUMBER(M29),M29,0)*Parametros!$K$6+IF(ISNUMBER(N29),N29,0)*Parametros!$K$7+IF(ISNUMBER(O29),O29,0)*Parametros!$K$8)/Parametros!$B$2)) -> 55 | Q29: =IF(F29="","",IF(COUNTIF(J29:O29,"D")>0,"Desiste",IF(IFERROR(P29,0)>=Parametros!$B$1,"Aprueba","No aprueba"))) -> No aprueba | T29: =IF($Q29="Aprueba",COUNTIF($Q$2:$Q29,"Aprueba"),"")
A30: =IF(F30="","",ROW()-1) -> 29 | B30: Pregrado Virtual | C30: 46224 | D30: Auxiliar gestor de vinculaciones | E30: 1006118253 | F30: Alex Esteban Angarita Lozano | G30: angarita20162001@gmail.com | H30: 3012268430 | I30: Karen Margarita Puerta | J30: 4 | K30: 4 | L30: 4 | M30: 4 | N30: 5 | O30: 3 | P30: =IF(F30="","",IF(COUNTIF(J30:O30,"D")>0,"",(IF(ISNUMBER(J30),J30,0)*Parametros!$K$4+IF(ISNUMBER(K30),K30,0)*Parametros!$K$5+IF(ISNUMBER(M30),M30,0)*Parametros!$K$6+IF(ISNUMBER(N30),N30,0)*Parametros!$K$7+IF(ISNUMBER(O30),O30,0)*Parametros!$K$8)/Parametros!$B$2)) -> 70 | Q30: =IF(F30="","",IF(COUNTIF(J30:O30,"D")>0,"Desiste",IF(IFERROR(P30,0)>=Parametros!$B$1,"Aprueba","No aprueba"))) -> Aprueba | T30: =IF($Q30="Aprueba",COUNTIF($Q$2:$Q30,"Aprueba"),"") -> 15
A31: =IF(F31="","",ROW()-1) -> 30 | B31: Pregrado Virtual | C31: 46224 | D31: Auxiliar gestor de vinculaciones | E31: 1073671475 | F31: Dana Yurleidy Lugo Castro | G31: danalugo12345@gmail.com | H31: 3147647259 | I31: Karen Margarita Puerta | K31: D | L31: D | M31: D | N31: D | O31: D | P31: =IF(F31="","",IF(COUNTIF(J31:O31,"D")>0,"",(IF(ISNUMBER(J31),J31,0)*Parametros!$K$4+IF(ISNUMBER(K31),K31,0)*Parametros!$K$5+IF(ISNUMBER(M31),M31,0)*Parametros!$K$6+IF(ISNUMBER(N31),N31,0)*Parametros!$K$7+IF(ISNUMBER(O31),O31,0)*Parametros!$K$8)/Parametros!$B$2)) | Q31: =IF(F31="","",IF(COUNTIF(J31:O31,"D")>0,"Desiste",IF(IFERROR(P31,0)>=Parametros!$B$1,"Aprueba","No aprueba"))) -> Desiste | T31: =IF($Q31="Aprueba",COUNTIF($Q$2:$Q31,"Aprueba"),"")
A32: =IF(F32="","",ROW()-1) -> 31 | B32: Pregrado Virtual | C32: 46224 | D32: Auxiliar gestor de vinculaciones | E32: 1013670551 | F32: Andersson Stiven Lozano Martinez | G32: andersson19892014@gmail.com | H32: 3244759449 | I32: Karen Margarita Puerta | J32: 3 | K32: 3 | L32: 3 | M32: 4 | N32: 5 | O32: 2 | P32: =IF(F32="","",IF(COUNTIF(J32:O32,"D")>0,"",(IF(ISNUMBER(J32),J32,0)*Parametros!$K$4+IF(ISNUMBER(K32),K32,0)*Parametros!$K$5+IF(ISNUMBER(M32),M32,0)*Parametros!$K$6+IF(ISNUMBER(N32),N32,0)*Parametros!$K$7+IF(ISNUMBER(O32),O32,0)*Parametros!$K$8)/Parametros!$B$2)) -> 57 | Q32: =IF(F32="","",IF(COUNTIF(J32:O32,"D")>0,"Desiste",IF(IFERROR(P32,0)>=Parametros!$B$1,"Aprueba","No aprueba"))) -> No aprueba | T32: =IF($Q32="Aprueba",COUNTIF($Q$2:$Q32,"Aprueba"),"")
A33: =IF(F33="","",ROW()-1) -> 32 | B33: Pregrado Virtual | C33: 46224 | D33: Auxiliar gestor de vinculaciones | E33: 1007343398 | F33: Duvan Alejandro Díaz Landinez | G33: Alejithodiax@gmail.com | H33: 3026595949 | I33: Karen Margarita Puerta | J33: 4 | K33: 4 | L33: 3 | M33: 3 | N33: 4 | O33: 4 | P33: =IF(F33="","",IF(COUNTIF(J33:O33,"D")>0,"",(IF(ISNUMBER(J33),J33,0)*Parametros!$K$4+IF(ISNUMBER(K33),K33,0)*Parametros!$K$5+IF(ISNUMBER(M33),M33,0)*Parametros!$K$6+IF(ISNUMBER(N33),N33,0)*Parametros!$K$7+IF(ISNUMBER(O33),O33,0)*Parametros!$K$8)/Parametros!$B$2)) -> 74 | Q33: =IF(F33="","",IF(COUNTIF(J33:O33,"D")>0,"Desiste",IF(IFERROR(P33,0)>=Parametros!$B$1,"Aprueba","No aprueba"))) -> Aprueba | T33: =IF($Q33="Aprueba",COUNTIF($Q$2:$Q33,"Aprueba"),"") -> 16
A34: =IF(F34="","",ROW()-1) -> 33 | B34: Pregrado Virtual | C34: 46224 | D34: Auxiliar gestor de vinculaciones | E34: 1007845676 | F34: Brandon Stiven Garces Arcos | G34: Brandongarces2@gmail.com | H34: 3223299162 | I34: Karen Margarita Puerta | J34: 4 | K34: 4 | L34: 3 | M34: 3 | N34: 3 | O34: 2 | P34: =IF(F34="","",IF(COUNTIF(J34:O34,"D")>0,"",(IF(ISNUMBER(J34),J34,0)*Parametros!$K$4+IF(ISNUMBER(K34),K34,0)*Parametros!$K$5+IF(ISNUMBER(M34),M34,0)*Parametros!$K$6+IF(ISNUMBER(N34),N34,0)*Parametros!$K$7+IF(ISNUMBER(O34),O34,0)*Parametros!$K$8)/Parametros!$B$2)) -> 50 | Q34: =IF(F34="","",IF(COUNTIF(J34:O34,"D")>0,"Desiste",IF(IFERROR(P34,0)>=Parametros!$B$1,"Aprueba","No aprueba"))) -> No aprueba | T34: =IF($Q34="Aprueba",COUNTIF($Q$2:$Q34,"Aprueba"),"")
A35: =IF(F35="","",ROW()-1) -> 34 | B35: Pregrado Virtual | C35: 46224 | D35: Auxiliar gestor de vinculaciones | E35: 1033772502 | F35: Juan Sebastian Acevedo Salazar | G35: juansevedo02@gmail.com | H35: 3025718737 | I35: Karen Margarita Puerta | J35: 4 | K35: 4 | L35: 2 | M35: 2 | N35: 4 | O35: 2 | P35: =IF(F35="","",IF(COUNTIF(J35:O35,"D")>0,"",(IF(ISNUMBER(J35),J35,0)*Parametros!$K$4+IF(ISNUMBER(K35),K35,0)*Parametros!$K$5+IF(ISNUMBER(M35),M35,0)*Parametros!$K$6+IF(ISNUMBER(N35),N35,0)*Parametros!$K$7+IF(ISNUMBER(O35),O35,0)*Parametros!$K$8)/Parametros!$B$2)) -> 52 | Q35: =IF(F35="","",IF(COUNTIF(J35:O35,"D")>0,"Desiste",IF(IFERROR(P35,0)>=Parametros!$B$1,"Aprueba","No aprueba"))) -> No aprueba | T35: =IF($Q35="Aprueba",COUNTIF($Q$2:$Q35,"Aprueba"),"")
A36: =IF(F36="","",ROW()-1) -> 35 | B36: Pregrado Virtual | C36: 46230 | D36: Auxiliar gestor de vinculaciones | E36: 1001340425 | F36: Elkin Dario González Alvarez | G36: elkingonzalezalvarez01@gmail.com | H36: 3003398465 | I36: Mayra Sofia Sanchez | J36: 5 | K36: 5 | L36: 3 | M36: 3 | N36: 4 | O36: 2 | P36: =IF(F36="","",IF(COUNTIF(J36:O36,"D")>0,"",(IF(ISNUMBER(J36),J36,0)*Parametros!$K$4+IF(ISNUMBER(K36),K36,0)*Parametros!$K$5+IF(ISNUMBER(M36),M36,0)*Parametros!$K$6+IF(ISNUMBER(N36),N36,0)*Parametros!$K$7+IF(ISNUMBER(O36),O36,0)*Parametros!$K$8)/Parametros!$B$2)) -> 57 | Q36: =IF(F36="","",IF(COUNTIF(J36:O36,"D")>0,"Desiste",IF(IFERROR(P36,0)>=Parametros!$B$1,"Aprueba","No aprueba"))) -> No aprueba | T36: =IF($Q36="Aprueba",COUNTIF($Q$2:$Q36,"Aprueba"),"")
A37: =IF(F37="","",ROW()-1) -> 36 | B37: Pregrado Virtual | C37: 46230 | D37: Auxiliar gestor de vinculaciones | E37: 1016001445 | F37: Norvey Ibarra Marquez | G37: norvey.ibarramarquez@gmail.com | H37: 3001425397 | I37: Mayra Sofia Sanchez | J37: 5 | K37: 5 | L37: 3 | M37: 4 | N37: 5 | O37: 3 | P37: =IF(F37="","",IF(COUNTIF(J37:O37,"D")>0,"",(IF(ISNUMBER(J37),J37,0)*Parametros!$K$4+IF(ISNUMBER(K37),K37,0)*Parametros!$K$5+IF(ISNUMBER(M37),M37,0)*Parametros!$K$6+IF(ISNUMBER(N37),N37,0)*Parametros!$K$7+IF(ISNUMBER(O37),O37,0)*Parametros!$K$8)/Parametros!$B$2)) -> 73 | Q37: =IF(F37="","",IF(COUNTIF(J37:O37,"D")>0,"Desiste",IF(IFERROR(P37,0)>=Parametros!$B$1,"Aprueba","No aprueba"))) -> Aprueba | T37: =IF($Q37="Aprueba",COUNTIF($Q$2:$Q37,"Aprueba"),"") -> 17
A38: =IF(F38="","",ROW()-1) -> 37 | B38: Pregrado Virtual | C38: 46230 | D38: Auxiliar gestor de vinculaciones | E38: 1111332054 | F38: Eimi Lisettc Páez Olaya | G38: Eimipaez941@gmail.com | H38: 3174216664 | I38: Mayra Sofia Sanchez | J38: 5 | K38: 5 | L38: 5 | M38: 5 | N38: 5 | O38: 3 | P38: =IF(F38="","",IF(COUNTIF(J38:O38,"D")>0,"",(IF(ISNUMBER(J38),J38,0)*Parametros!$K$4+IF(ISNUMBER(K38),K38,0)*Parametros!$K$5+IF(ISNUMBER(M38),M38,0)*Parametros!$K$6+IF(ISNUMBER(N38),N38,0)*Parametros!$K$7+IF(ISNUMBER(O38),O38,0)*Parametros!$K$8)/Parametros!$B$2)) -> 75 | Q38: =IF(F38="","",IF(COUNTIF(J38:O38,"D")>0,"Desiste",IF(IFERROR(P38,0)>=Parametros!$B$1,"Aprueba","No aprueba"))) -> Aprueba | T38: =IF($Q38="Aprueba",COUNTIF($Q$2:$Q38,"Aprueba"),"") -> 18
A39: =IF(F39="","",ROW()-1) -> 38 | B39: Pregrado Virtual | C39: 46230 | D39: Auxiliar gestor de vinculaciones | E39: 1012383996 | F39: Haidivy Lorena Orosco Viracacha | G39: haidivyo@hotmail.com | H39: 3163032130 | I39: Mayra Sofia Sanchez | J39: 5 | K39: 5 | L39: 5 | M39: 4 | N39: 5 | O39: 3 | P39: =IF(F39="","",IF(COUNTIF(J39:O39,"D")>0,"",(IF(ISNUMBER(J39),J39,0)*Parametros!$K$4+IF(ISNUMBER(K39),K39,0)*Parametros!$K$5+IF(ISNUMBER(M39),M39,0)*Parametros!$K$6+IF(ISNUMBER(N39),N39,0)*Parametros!$K$7+IF(ISNUMBER(O39),O39,0)*Parametros!$K$8)/Parametros!$B$2)) -> 73 | Q39: =IF(F39="","",IF(COUNTIF(J39:O39,"D")>0,"Desiste",IF(IFERROR(P39,0)>=Parametros!$B$1,"Aprueba","No aprueba"))) -> Aprueba | T39: =IF($Q39="Aprueba",COUNTIF($Q$2:$Q39,"Aprueba"),"") -> 19
A40: =IF(F40="","",ROW()-1) -> 39 | B40: Pregrado Virtual | C40: 46230 | D40: Auxiliar gestor de vinculaciones | E40: 1012390029 | F40: Luisa Maria Hormaza Hernández | G40: fercha0898@hotmail.com | H40: 3105887044 | I40: Mayra Sofia Sanchez | J40: 5 | K40: 5 | L40: 4 | M40: 4 | N40: 5 | O40: 3 | P40: =IF(F40="","",IF(COUNTIF(J40:O40,"D")>0,"",(IF(ISNUMBER(J40),J40,0)*Parametros!$K$4+IF(ISNUMBER(K40),K40,0)*Parametros!$K$5+IF(ISNUMBER(M40),M40,0)*Parametros!$K$6+IF(ISNUMBER(N40),N40,0)*Parametros!$K$7+IF(ISNUMBER(O40),O40,0)*Parametros!$K$8)/Parametros!$B$2)) -> 73 | Q40: =IF(F40="","",IF(COUNTIF(J40:O40,"D")>0,"Desiste",IF(IFERROR(P40,0)>=Parametros!$B$1,"Aprueba","No aprueba"))) -> Aprueba | T40: =IF($Q40="Aprueba",COUNTIF($Q$2:$Q40,"Aprueba"),"") -> 20
...

Sheet OJT
A1: N° | B1: No. DOCUMENTO | C1: NOMBRE COMPLETO | D1: CAMPAÑA | E1: NOTA DE APROBACIÓN | F1: DÍA | G1: FECHA | H1: MATRÍCULAS | I1: ADHERENCIA | J1: ACTITUD (1-5) | K1: Aprueba OJT | L1: OBSERVACIONES
A2: =IFERROR(IF(INDEX(Registro!$E$2:$E$100,MATCH(1,Registro!$T$2:$T$100,0))="","", 1),"") -> 1 | B2: =IFERROR(INDEX(Registro!$E$2:$E$100,MATCH(1,Registro!$T$2:$T$100,0)),"") -> 1193156026 | C2: =IFERROR(INDEX(Registro!$F$2:$F$100,MATCH(1,Registro!$T$2:$T$100,0)),"") -> Sara Isabel Molina Sánchez | D2: =IFERROR(INDEX(Registro!$B$2:$B$100,MATCH(1,Registro!$T$2:$T$100,0)),"") -> Posgrados | E2: =IFERROR(INDEX(Registro!$P$2:$P$100,MATCH(1,Registro!$T$2:$T$100,0)),"") -> 72 | F2: 1
F3: 2
F4: 3
F5: 4
F6: 5
A7: =IFERROR(IF(INDEX(Registro!$E$2:$E$100,MATCH(2,Registro!$T$2:$T$100,0))="","", 2),"") -> 2 | B7: =IFERROR(INDEX(Registro!$E$2:$E$100,MATCH(2,Registro!$T$2:$T$100,0)),"") -> 1016001652 | C7: =IFERROR(INDEX(Registro!$F$2:$F$100,MATCH(2,Registro!$T$2:$T$100,0)),"") -> Helen Sofia Calderon Camelo | D7: =IFERROR(INDEX(Registro!$B$2:$B$100,MATCH(2,Registro!$T$2:$T$100,0)),"") -> Posgrados | E7: =IFERROR(INDEX(Registro!$P$2:$P$100,MATCH(2,Registro!$T$2:$T$100,0)),"") -> 70 | F7: 1
F8: 2
F9: 3
F10: 4
F11: 5
A12: =IFERROR(IF(INDEX(Registro!$E$2:$E$100,MATCH(3,Registro!$T$2:$T$100,0))="","", 3),"") -> 3 | B12: =IFERROR(INDEX(Registro!$E$2:$E$100,MATCH(3,Registro!$T$2:$T$100,0)),"") -> 1001314657 | C12: =IFERROR(INDEX(Registro!$F$2:$F$100,MATCH(3,Registro!$T$2:$T$100,0)),"") -> Thomas Bernardo Fernandez Laverde | D12: =IFERROR(INDEX(Registro!$B$2:$B$100,MATCH(3,Registro!$T$2:$T$100,0)),"") -> Posgrados | E12: =IFERROR(INDEX(Registro!$P$2:$P$100,MATCH(3,Registro!$T$2:$T$100,0)),"") -> 72 | F12: 1
F13: 2
F14: 3
F15: 4
F16: 5
A17: =IFERROR(IF(INDEX(Registro!$E$2:$E$100,MATCH(4,Registro!$T$2:$T$100,0))="","", 4),"") -> 4 | B17: =IFERROR(INDEX(Registro!$E$2:$E$100,MATCH(4,Registro!$T$2:$T$100,0)),"") -> 1033096735 | C17: =IFERROR(INDEX(Registro!$F$2:$F$100,MATCH(4,Registro!$T$2:$T$100,0)),"") -> Pablo Steven Ochoa Rodriguez | D17: =IFERROR(INDEX(Registro!$B$2:$B$100,MATCH(4,Registro!$T$2:$T$100,0)),"") -> Posgrados | E17: =IFERROR(INDEX(Registro!$P$2:$P$100,MATCH(4,Registro!$T$2:$T$100,0)),"") -> 81 | F17: 1
F18: 2
F19: 3
F20: 4
F21: 5
A22: =IFERROR(IF(INDEX(Registro!$E$2:$E$100,MATCH(5,Registro!$T$2:$T$100,0))="","", 5),"") -> 5 | B22: =IFERROR(INDEX(Registro!$E$2:$E$100,MATCH(5,Registro!$T$2:$T$100,0)),"") -> 1004961429 | C22: =IFERROR(INDEX(Registro!$F$2:$F$100,MATCH(5,Registro!$T$2:$T$100,0)),"") -> Jhon Stiven Marin Valencia | D22: =IFERROR(INDEX(Registro!$B$2:$B$100,MATCH(5,Registro!$T$2:$T$100,0)),"") -> Posgrados | E22: =IFERROR(INDEX(Registro!$P$2:$P$100,MATCH(5,Registro!$T$2:$T$100,0)),"") -> 73 | F22: 1
F23: 2
F24: 3
F25: 4
F26: 5
A27: =IFERROR(IF(INDEX(Registro!$E$2:$E$100,MATCH(6,Registro!$T$2:$T$100,0))="","", 6),"") -> 6 | B27: =IFERROR(INDEX(Registro!$E$2:$E$100,MATCH(6,Registro!$T$2:$T$100,0)),"") -> 53121281 | C27: =IFERROR(INDEX(Registro!$F$2:$F$100,MATCH(6,Registro!$T$2:$T$100,0)),"") -> Yulieth Paola Rodriguez Cañon | D27: =IFERROR(INDEX(Registro!$B$2:$B$100,MATCH(6,Registro!$T$2:$T$100,0)),"") -> Posgrados | E27: =IFERROR(INDEX(Registro!$P$2:$P$100,MATCH(6,Registro!$T$2:$T$100,0)),"") -> 78 | F27: 1
F28: 2
F29: 3
F30: 4
F31: 5
A32: =IFERROR(IF(INDEX(Registro!$E$2:$E$100,MATCH(7,Registro!$T$2:$T$100,0))="","", 7),"") -> 7 | B32: =IFERROR(INDEX(Registro!$E$2:$E$100,MATCH(7,Registro!$T$2:$T$100,0)),"") -> 1024585365 | C32: =IFERROR(INDEX(Registro!$F$2:$F$100,MATCH(7,Registro!$T$2:$T$100,0)),"") -> Cristian David Celis Garcia | D32: =IFERROR(INDEX(Registro!$B$2:$B$100,MATCH(7,Registro!$T$2:$T$100,0)),"") -> Posgrados | E32: =IFERROR(INDEX(Registro!$P$2:$P$100,MATCH(7,Registro!$T$2:$T$100,0)),"") -> 73 | F32: 1
F33: 2
F34: 3
F35: 4
F36: 5
A37: =IFERROR(IF(INDEX(Registro!$E$2:$E$100,MATCH(8,Registro!$T$2:$T$100,0))="","", 8),"") -> 8 | B37: =IFERROR(INDEX(Registro!$E$2:$E$100,MATCH(8,Registro!$T$2:$T$100,0)),"") -> 1000547797 | C37: =IFERROR(INDEX(Registro!$F$2:$F$100,MATCH(8,Registro!$T$2:$T$100,0)),"") -> Kamy Lizeth Rios Gomez | D37: =IFERROR(INDEX(Registro!$B$2:$B$100,MATCH(8,Registro!$T$2:$T$100,0)),"") -> Posgrados | E37: =IFERROR(INDEX(Registro!$P$2:$P$100,MATCH(8,Registro!$T$2:$T$100,0)),"") -> 90 | F37: 1
F38: 2
F39: 3
F40: 4
...

Sheet Resumen
A1: ESTADISTICAS GENERALES DE FORMACION Y ONBOARDING
A2: 1. Estadisticas de Formacion Teorica (Hoja Registro)
A4: Participantes por Campana y Estado de Onboarding | G4: Nota Promedio de Onboarding por Campana | K4: Participantes por Cargo y Estado de Onboarding
A5: Cantidad | B5: Etiquetas de columna | G5: Etiquetas de fila | H5: Nota Promedio | K5: Cantidad | L5: Etiquetas de columna
A6: Etiquetas de fila | B6: Aprueba | C6: No aprueba | D6: Total general | G6: Posgrados | H6: 70.791667 | K6: Etiquetas de fila | L6: Aprueba | M6: No aprueba | N6: Total general
A7: Posgrados | B7: 13 | C7: 11 | D7: 24 | G7: Pregrado Virtual | H7: 3.7 | K7: Auxiliar gestor de vinculaciones | L7: 13 | M7: 21 | N7: 34
A8: Pregrado Virtual | C8: 10 | D8: 10 | G8: Total general | H8: 51.058824 | K8: Total general | L8: 13 | M8: 21 | N8: 34
A9: Total general | B9: 13 | C9: 21 | D9: 34
A18: 2. Estadisticas de On-the-Job Training - OJT (Hoja OJT Aprobados)
A20: Aprobados OJT por Campana | G20: Nota Promedio de OJT por Campana
A21: Cantidad | B21: Etiquetas de columna | G21: Etiquetas de fila | H21: Nota Promedio
A22: Etiquetas de fila | B22: Aprueba | C22: Total general | G22: Posgrados | H22: 78
A23: Posgrados | B23: 13 | C23: 13 | G23: Total general | H23: 78
A24: Total general | B24: 13 | C24: 13
A28: RESUMEN DE INGRESOS A FORMACIÓN (OJT)
A30: Total de personas registradas | B30: =COUNT(Registro!A2:A96) -> 46
A31: Total aprobados | B31: =COUNTIF(Registro!Q2:Q96,"Aprueba") -> 26
A32: Total no aprobados | B32: =COUNTIF(Registro!Q2:Q96,"No aprueba") -> 19
A33: % de aprobación | B33: =IFERROR(B31/B30,0) -> 0.56521739
A34: Nota promedio general | B34: =IFERROR(AVERAGE(Registro!P2:P96),"") -> 67.355556
A35: Total retirados | B35: =COUNTIF(Registro!$Q$2:$Q$500,"Desiste") -> 1
A36: Total en formación | B36: =COUNTIFS(Registro!$F$2:$F$500,"<>",Registro!$Q$2:$Q$500,"") -> 0
A39: REGISTROS POR CAMPAÑA
A40: Campaña | B40: N° personas | C40: N° aprobados | D40: % aprobación
A41: Pregrado Virtual | B41: =COUNTIF(Registro!$B$2:$B$500,A41) -> 22 | C41: =COUNTIFS(Registro!$B$2:$B$500,A41,Registro!$Q$2:$Q$500,"Aprueba") -> 13 | D41: =IFERROR(C41/B41,0) -> 0.59090909
A42: Pregrado Presencial | B42: =COUNTIF(Registro!$B$2:$B$500,A42) -> 0 | C42: =COUNTIFS(Registro!$B$2:$B$500,A42,Registro!$Q$2:$Q$500,"Aprueba") -> 0 | D42: =IFERROR(C42/B42,0) -> 0
A43: Posgrados | B43: =COUNTIF(Registro!$B$2:$B$500,A43) -> 24 | C43: =COUNTIFS(Registro!$B$2:$B$500,A43,Registro!$Q$2:$Q$500,"Aprueba") -> 13 | D43: =IFERROR(C43/B43,0) -> 0.54166667
B44: =COUNTIF(Registro!$B$2:$B$500,A44) -> 0 | C44: =COUNTIFS(Registro!$B$2:$B$500,A44,Registro!$Q$2:$Q$500,"Aprueba") -> 0 | D44: =IFERROR(C44/B44,0) -> 0
B45: =COUNTIF(Registro!$B$2:$B$500,A45) -> 0 | C45: =COUNTIFS(Registro!$B$2:$B$500,A45,Registro!$Q$2:$Q$500,"Aprueba") -> 0 | D45: =IFERROR(C45/B45,0) -> 0
A48: REGISTROS POR FORMADOR
A49: Formador | B49: N° personas | C49: N° aprobados | D49: Nota promedio
A50: Karen Margarita Puerta | B50: =COUNTIF(Registro!$I$2:$I$500,A50) -> 10 | C50: =COUNTIFS(Registro!$I$2:$I$500,A50,Registro!$Q$2:$Q$500,"Aprueba") -> 3 | D50: =IFERROR(AVERAGEIF(Registro!$I$2:$I$500,A50,Registro!$P$2:$P$500),0) -> 55
A51: Mayra Sofia Sanchez | B51: =COUNTIF(Registro!$I$2:$I$500,A51) -> 12 | C51: =COUNTIFS(Registro!$I$2:$I$500,A51,Registro!$Q$2:$Q$500,"Aprueba") -> 10 | D51: =IFERROR(AVERAGEIF(Registro!$I$2:$I$500,A51,Registro!$P$2:$P$500),0) -> 69.666667
A52: Monica Sanchez | B52: =COUNTIF(Registro!$I$2:$I$500,A52) -> 0 | C52: =COUNTIFS(Registro!$I$2:$I$500,A52,Registro!$Q$2:$Q$500,"Aprueba") -> 0 | D52: =IFERROR(AVERAGEIF(Registro!$I$2:$I$500,A52,Registro!$P$2:$P$500),0) -> 0
A53: Todas | B53: =COUNTIF(Registro!$I$2:$I$500,A53) -> 0 | C53: =COUNTIFS(Registro!$I$2:$I$500,A53,Registro!$Q$2:$Q$500,"Aprueba") -> 0 | D53: =IFERROR(AVERAGEIF(Registro!$I$2:$I$500,A53,Registro!$P$2:$P$500),0) -> 0

Sheet Resumen OJT
A1: RESUMEN DE APROBADOS - HOJA OJT
A3: Total de aprobados en OJT | B3: =SUMPRODUCT(--(#REF!<>"")) -> #REF!
A4: Nota promedio (aprobados) | B4: =IFERROR(AVERAGE(#REF!),"")
A5: Nota más alta | B5: =IFERROR(MAX(#REF!),"")
A6: Nota más baja | B6: =IFERROR(MIN(#REF!),"")
A9: APROBADOS POR CAMPAÑA (OJT)
A10: Campaña | B10: N° aprobados | C10: % del total | D10: Nota promedio | E10: Nota mínima | F10: Nota máxima
A11: Pregrado Virtual | B11: =COUNTIF(#REF!,A11) -> #REF! | C11: =IFERROR(B11/$B$3,"") | D11: =IFERROR(AVERAGEIF(#REF!,A11,#REF!),"") | E11: =IFERROR(_xlfn.MINIFS(#REF!,#REF!,A11),"") | F11: =IFERROR(_xlfn.MAXIFS(#REF!,#REF!,A11),"")
A12: Pregrado Presencial | B12: =COUNTIF(#REF!,A12) -> #REF! | C12: =IFERROR(B12/$B$3,"") | D12: =IFERROR(AVERAGEIF(#REF!,A12,#REF!),"") | E12: =IFERROR(_xlfn.MINIFS(#REF!,#REF!,A12),"") | F12: =IFERROR(_xlfn.MAXIFS(#REF!,#REF!,A12),"")
A13: Posgrados | B13: =COUNTIF(#REF!,A13) -> #REF! | C13: =IFERROR(B13/$B$3,"") | D13: =IFERROR(AVERAGEIF(#REF!,A13,#REF!),"") | E13: =IFERROR(_xlfn.MINIFS(#REF!,#REF!,A13),"") | F13: =IFERROR(_xlfn.MAXIFS(#REF!,#REF!,A13),"")
A14: Comercial B2B | B14: =COUNTIF(#REF!,A14) -> #REF! | C14: =IFERROR(B14/$B$3,"") | D14: =IFERROR(AVERAGEIF(#REF!,A14,#REF!),"") | E14: =IFERROR(_xlfn.MINIFS(#REF!,#REF!,A14),"") | F14: =IFERROR(_xlfn.MAXIFS(#REF!,#REF!,A14),"")
A15: TOTAL | B15: =SUM(B11:B14) -> #REF! | C15: =IFERROR(B15/$B$3,"") | D15: =IFERROR(AVERAGE(#REF!),"") | E15: =IFERROR(MIN(#REF!),"") | F15: =IFERROR(MAX(#REF!),"")

Sheet Parametros
A1: Nota minima para aprobar | B1: 70 | C1: (edita este valor para ajustar el umbral de aprobacion)
A2: Escala de calificación (máximo por ítem) | B2: 5 | C2: (cada ítem se califica de 1 a 5)
D3: CAMPAÑA | E3: CARGO | F3: FORMADOR | G3: ESTADO DEL PROCESO | H3: APRUEBA | J3: ITEM DE EVALUACIÓN | K3: PESO %
D4: Pregrado Virtual | E4: Gestor vinculaciones Junior | F4: Karen Margarita Puerta | G4: En formación | H4: Aprueba | J4: Presentación personal | K4: 5
D5: Pregrado Presencial | E5: Gestor vinculaciones Senior | F5: Mayra Sofia Sanchez | G5: OJT | H5: No aprueba | J5: Participación y puntualidad | K5: 10
D6: Posgrados | E6: Auxiliar gestor de vinculaciones | F6: Monica Sanchez | G6: Retirado | J6: Evaluación conocimiento & role play | K6: 10
D7: Comercial B2B | F7: Todas | J7: Simulación con IA | K7: 20
J8: Evaluación final (clínica de ventas) | K8: 50
J9: Evaluación conocimiento (Día 2) | K9: 5
D12: Escala de evaluación
D14: 90–100 = 5
D15: 80–89 = 4
D16: 70–79 = 3
D17: 60–69 = 2
D18: 0–59 = 1
