Workbook
Name Lista_Aprueba: Parametros!$H$4:$H$30
Name Lista_Campana: Parametros!$D$4:$D$30
Name Lista_Cargo: Parametros!$E$4:$E$30
Name Lista_Estado: Parametros!$G$4:$G$29
Name Lista_Formador: Parametros!$F$4:$F$30

Sheet Registro
A1: No. | B1: CAMPAÑA | C1: FECHA DE INGRESO A FORMACIÓN | D1: CARGO | E1: No. DOCUMENTO | F1: NOMBRE COMPLETO | G1: CORREO ELECTRÓNICO | H1: TELÉFONO MÓVIL | I1: FORMADOR | J1: PRESENTACIÓN PERSONAL 5% | K1: PARTICIPACIÓN Y PUNTUALIDAD 10% | L1: EVALUACIÓN CONOCIMIENTO (DIA 2) 5% | M1: EVALUACIÓN TÉCNICA 10% | N1: SIMULACIÓN CON IA 20% | O1: EVALUACIÓN FINAL (CLÍNICA DE VENTAS) 50% | P1: NOTA FINAL | Q1: APRUEBA | R1: OBSERVACIONES | T1: AUX - ORDEN APROBADO (no borrar)
A2: =IF(F2="","",ROW()-1) -> 1 | B2: Posgrados | C2: 46204 | D2: Auxiliar gestor de vinculaciones | E2: 1193156026 | F2: Sara Isabel Molina Sánchez | G2: Molinasara453@gmail.com | H2: 3245742876 | I2: Todas | J2: 4 | K2: 5 | M2: 4 | N2: 5 | O2: 3 | P2: =IF(F2="","",(J2*Parametros!$K$4+K2*Parametros!$K$5+M2*Parametros!$K$6+N2*Parametros!$K$7+O2*Parametros!$K$8)/Parametros!$B$2) -> 72 | Q2: =IF(F2="","",IF(P2>=Parametros!$B$1,"Aprueba","No aprueba")) -> Aprueba | T2: =IF($Q2="Aprueba",COUNTIF($Q$2:$Q2,"Aprueba"),"") -> 1
A3: =IF(F3="","",ROW()-1) -> 2 | B3: Posgrados | C3: 46204 | D3: Auxiliar gestor de vinculaciones | E3: 1022988349 | F3: Michelle Geraldine Bejarano Torres | G3: michelletorres2593@hotmail.com | H3: 3123702518 | I3: Todas | J3: 4 | K3: 2 | M3: 4 | N3: 4 | O3: 3 | P3: =IF(F3="","",(J3*Parametros!$K$4+K3*Parametros!$K$5+M3*Parametros!$K$6+N3*Parametros!$K$7+O3*Parametros!$K$8)/Parametros!$B$2) -> 62 | Q3: =IF(F3="","",IF(P3>=Parametros!$B$1,"Aprueba","No aprueba")) -> No aprueba | T3: =IF($Q3="Aprueba",COUNTIF($Q$2:$Q3,"Aprueba"),"")
A4: =IF(F4="","",ROW()-1) -> 3 | B4: Posgrados | C4: 46204 | D4: Auxiliar gestor de vinculaciones | E4: 1016001652 | F4: Helen Sofia Calderon Camelo | G4: helencalderon910@gmail.com | H4: ‪3239227093‬ | I4: Todas | J4: 4 | K4: 4 | M4: 4 | N4: 5 | O4: 3 | P4: =IF(F4="","",(J4*Parametros!$K$4+K4*Parametros!$K$5+M4*Parametros!$K$6+N4*Parametros!$K$7+O4*Parametros!$K$8)/Parametros!$B$2) -> 70 | Q4: =IF(F4="","",IF(P4>=Parametros!$B$1,"Aprueba","No aprueba")) -> Aprueba | T4: =IF($Q4="Aprueba",COUNTIF($Q$2:$Q4,"Aprueba"),"") -> 2
A5: =IF(F5="","",ROW()-1) -> 4 | B5: Posgrados | C5: 46204 | D5: Auxiliar gestor de vinculaciones | E5: 1012385263 | F5: Cindy Paola Cuellar Montoya | G5: Cindypaolacuellar@gmail.com | H5: 3172616867 | I5: Todas | J5: 3 | K5: 3 | M5: 3 | N5: 5 | O5: 3 | P5: =IF(F5="","",(J5*Parametros!$K$4+K5*Parametros!$K$5+M5*Parametros!$K$6+N5*Parametros!$K$7+O5*Parametros!$K$8)/Parametros!$B$2) -> 65 | Q5: =IF(F5="","",IF(P5>=Parametros!$B$1,"Aprueba","No aprueba")) -> No aprueba | R5: Llega tarde | T5: =IF($Q5="Aprueba",COUNTIF($Q$2:$Q5,"Aprueba"),"")
A6: =IF(F6="","",ROW()-1) -> 5 | B6: Posgrados | C6: 46204 | D6: Auxiliar gestor de vinculaciones | E6: 1001314657 | F6: Thomas Bernardo Fernandez Laverde | G6: tfernandezlaverde@gmail.com | H6: 3103798566 | I6: Todas | J6: 4 | K6: 5 | M6: 4 | N6: 5 | O6: 3 | P6: =IF(F6="","",(J6*Parametros!$K$4+K6*Parametros!$K$5+M6*Parametros!$K$6+N6*Parametros!$K$7+O6*Parametros!$K$8)/Parametros!$B$2) -> 72 | Q6: =IF(F6="","",IF(P6>=Parametros!$B$1,"Aprueba","No aprueba")) -> Aprueba | T6: =IF($Q6="Aprueba",COUNTIF($Q$2:$Q6,"Aprueba"),"") -> 3
A7: =IF(F7="","",ROW()-1) -> 6 | B7: Posgrados | C7: 46204 | D7: Auxiliar gestor de vinculaciones | E7: 52956322 | F7: Julie Caterine Villalobos Ortiz | G7: Juliecaterine23@gmail.com | H7: 3213264788 | I7: Todas | J7: 5 | K7: 5 | M7: 4 | N7: 4 | O7: 3 | P7: =IF(F7="","",(J7*Parametros!$K$4+K7*Parametros!$K$5+M7*Parametros!$K$6+N7*Parametros!$K$7+O7*Parametros!$K$8)/Parametros!$B$2) -> 69 | Q7: =IF(F7="","",IF(P7>=Parametros!$B$1,"Aprueba","No aprueba")) -> No aprueba | T7: =IF($Q7="Aprueba",COUNTIF($Q$2:$Q7,"Aprueba"),"")
A8: =IF(F8="","",ROW()-1) -> 7 | B8: Posgrados | C8: 46204 | D8: Auxiliar gestor de vinculaciones | E8: 10191156098 | F8: Yaricet Bricet Cárcamo Morales | G8: Yaricetbricet@gmail.com | H8: 3008533917 | I8: Todas | J8: 4 | K8: 4 | M8: 4 | N8: 3 | O8: 3 | P8: =IF(F8="","",(J8*Parametros!$K$4+K8*Parametros!$K$5+M8*Parametros!$K$6+N8*Parametros!$K$7+O8*Parametros!$K$8)/Parametros!$B$2) -> 62 | Q8: =IF(F8="","",IF(P8>=Parametros!$B$1,"Aprueba","No aprueba")) -> No aprueba | T8: =IF($Q8="Aprueba",COUNTIF($Q$2:$Q8,"Aprueba"),"")
A9: =IF(F9="","",ROW()-1) -> 8 | B9: Posgrados | C9: 46204 | D9: Auxiliar gestor de vinculaciones | E9: 1033096735 | F9: Pablo Steven Ochoa Rodriguez | G9: Pablorodriguez8q@gmail.com | H9: 3196588439 | I9: Todas | J9: 3 | K9: 4 | M9: 5 | N9: 5 | O9: 4 | P9: =IF(F9="","",(J9*Parametros!$K$4+K9*Parametros!$K$5+M9*Parametros!$K$6+N9*Parametros!$K$7+O9*Parametros!$K$8)/Parametros!$B$2) -> 81 | Q9: =IF(F9="","",IF(P9>=Parametros!$B$1,"Aprueba","No aprueba")) -> Aprueba | T9: =IF($Q9="Aprueba",COUNTIF($Q$2:$Q9,"Aprueba"),"") -> 4
A10: =IF(F10="","",ROW()-1) -> 9 | B10: Posgrados | C10: 46204 | D10: Auxiliar gestor de vinculaciones | E10: 1000219286 | F10: Lucia Fernanda Cruz Canchila | G10: Luciacruz0414@gmail.com | H10: 3005145730 | I10: Todas | J10: 4 | K10: 2 | M10: 5 | N10: 5 | O10: 3 | P10: =IF(F10="","",(J10*Parametros!$K$4+K10*Parametros!$K$5+M10*Parametros!$K$6+N10*Parametros!$K$7+O10*Parametros!$K$8)/Parametros!$B$2) -> 68 | Q10: =IF(F10="","",IF(P10>=Parametros!$B$1,"Aprueba","No aprueba")) -> No aprueba | R10: Llega tarde | T10: =IF($Q10="Aprueba",COUNTIF($Q$2:$Q10,"Aprueba"),"")
A11: =IF(F11="","",ROW()-1) -> 10 | B11: Posgrados | C11: 46204 | D11: Auxiliar gestor de vinculaciones | E11: 1004961429 | F11: Jhon Stiven Marin Valencia | G11: jhonstivenmarin02@gmail.com | H11: 3219466413 | I11: Todas | J11: 3 | K11: 3 | M11: 4 | N11: 4 | O11: 4 | P11: =IF(F11="","",(J11*Parametros!$K$4+K11*Parametros!$K$5+M11*Parametros!$K$6+N11*Parametros!$K$7+O11*Parametros!$K$8)/Parametros!$B$2) -> 73 | Q11: =IF(F11="","",IF(P11>=Parametros!$B$1,"Aprueba","No aprueba")) -> Aprueba | R11: Llega tarde | T11: =IF($Q11="Aprueba",COUNTIF($Q$2:$Q11,"Aprueba"),"") -> 5
A12: =IF(F12="","",ROW()-1) -> 11 | B12: Posgrados | C12: 46204 | D12: Auxiliar gestor de vinculaciones | E12: 53121281 | F12: Yulieth Paola Rodriguez Cañon | G12: ypaolarodriguez14@gmail.com | H12: 3112142736 | I12: Todas | J12: 4 | K12: 4 | M12: 3 | N12: 5 | O12: 4 | P12: =IF(F12="","",(J12*Parametros!$K$4+K12*Parametros!$K$5+M12*Parametros!$K$6+N12*Parametros!$K$7+O12*Parametros!$K$8)/Parametros!$B$2) -> 78 | Q12: =IF(F12="","",IF(P12>=Parametros!$B$1,"Aprueba","No aprueba")) -> Aprueba | T12: =IF($Q12="Aprueba",COUNTIF($Q$2:$Q12,"Aprueba"),"") -> 6
A13: =IF(F13="","",ROW()-1) -> 12 | B13: Posgrados | C13: 46204 | D13: Auxiliar gestor de vinculaciones | E13: 1019138287 | F13: Natalia Fernanda Mendieta Oicata | G13: nataliamendieta2025@gmail.com | H13: 3003020830 | I13: Todas | J13: 5 | K13: 5 | M13: 3 | N13: 4 | O13: 3 | P13: =IF(F13="","",(J13*Parametros!$K$4+K13*Parametros!$K$5+M13*Parametros!$K$6+N13*Parametros!$K$7+O13*Parametros!$K$8)/Parametros!$B$2) -> 67 | Q13: =IF(F13="","",IF(P13>=Parametros!$B$1,"Aprueba","No aprueba")) -> No aprueba | T13: =IF($Q13="Aprueba",COUNTIF($Q$2:$Q13,"Aprueba"),"")
A14: =IF(F14="","",ROW()-1) -> 13 | B14: Posgrados | C14: 46211 | D14: Auxiliar gestor de vinculaciones | E14: 1019145849 | F14: Jhonatan David Londoño Baldovino | G14: Jdlbaldovino199@gmail.com | H14: 3208836403 | I14: Todas | J14: 4 | K14: 4 | L14: 3 | M14: 3 | N14: 3 | O14: 2 | P14: =IF(F14="","",(J14*Parametros!$K$4+K14*Parametros!$K$5+L14*Parametros!$K$6+M14*Parametros!$K$7+N14*Parametros!$K$8+O14*Parametros!$K$9)/Parametros!$B$2) -> 62 | Q14: =IF(F14="","",IF(P14>=Parametros!$B$1,"Aprueba","No aprueba")) -> No aprueba | T14: =IF($Q14="Aprueba",COUNTIF($Q$2:$Q14,"Aprueba"),"")
A15: =IF(F15="","",ROW()-1) -> 14 | B15: Posgrados | C15: 46211 | D15: Auxiliar gestor de vinculaciones | E15: 1001056884 | F15: David Felipe Hernández Hernández | G15: david.hernandez.dtk@gmail.com | H15: 3028250517 | I15: Todas | J15: 4 | K15: 4 | L15: 3 | M15: 3 | N15: 3 | O15: 3 | P15: =IF(F15="","",(J15*Parametros!$K$4+K15*Parametros!$K$5+L15*Parametros!$K$6+M15*Parametros!$K$7+N15*Parametros!$K$8+O15*Parametros!$K$9)/Parametros!$B$2) -> 63 | Q15: =IF(F15="","",IF(P15>=Parametros!$B$1,"Aprueba","No aprueba")) -> No aprueba | T15: =IF($Q15="Aprueba",COUNTIF($Q$2:$Q15,"Aprueba"),"")
A16: =IF(F16="","",ROW()-1) -> 15 | B16: Posgrados | C16: 46211 | D16: Auxiliar gestor de vinculaciones | E16: 1024585365 | F16: Cristian David Celis Garcia | G16: cristianceliss9719@gmail.com | H16: 3216686201 | I16: Todas | J16: 4 | K16: 4 | L16: 3 | M16: 3 | N16: 4 | O16: 3 | P16: =IF(F16="","",(J16*Parametros!$K$4+K16*Parametros!$K$5+L16*Parametros!$K$6+M16*Parametros!$K$7+N16*Parametros!$K$8+O16*Parametros!$K$9)/Parametros!$B$2) -> 73 | Q16: =IF(F16="","",IF(P16>=Parametros!$B$1,"Aprueba","No aprueba")) -> Aprueba | R16: Llega tarde | T16: =IF($Q16="Aprueba",COUNTIF($Q$2:$Q16,"Aprueba"),"") -> 7
A17: =IF(F17="","",ROW()-1) -> 16 | B17: Posgrados | C17: 46211 | D17: Auxiliar gestor de vinculaciones | E17: 1000547797 | F17: Kamy Lizeth Rios Gomez | G17: riosgomezkamy@gmail.com | H17: 3112534635 | I17: Todas | J17: 5 | K17: 4 | L17: 2 | M17: 5 | N17: 5 | O17: 3 | P17: =IF(F17="","",(J17*Parametros!$K$4+K17*Parametros!$K$5+L17*Parametros!$K$6+M17*Parametros!$K$7+N17*Parametros!$K$8+O17*Parametros!$K$9)/Parametros!$B$2) -> 90 | Q17: =IF(F17="","",IF(P17>=Parametros!$B$1,"Aprueba","No aprueba")) -> Aprueba | T17: =IF($Q17="Aprueba",COUNTIF($Q$2:$Q17,"Aprueba"),"") -> 8
A18: =IF(F18="","",ROW()-1) -> 17 | B18: Posgrados | C18: 46211 | D18: Auxiliar gestor de vinculaciones | E18: 1023867138 | F18: Yisell Dayana Castro González | G18: Gonzalezdayanna730@gmail.com | H18: 3143600585 | I18: Todas | J18: 4 | K18: 4 | L18: 3 | M18: 3 | N18: 4 | O18: 2 | P18: =IF(F18="","",(J18*Parametros!$K$4+K18*Parametros!$K$5+L18*Parametros!$K$6+M18*Parametros!$K$7+N18*Parametros!$K$8+O18*Parametros!$K$9)/Parametros!$B$2) -> 72 | Q18: =IF(F18="","",IF(P18>=Parametros!$B$1,"Aprueba","No aprueba")) -> Aprueba | T18: =IF($Q18="Aprueba",COUNTIF($Q$2:$Q18,"Aprueba"),"") -> 9
A19: =IF(F19="","",ROW()-1) -> 18 | B19: Posgrados | C19: 46211 | D19: Auxiliar gestor de vinculaciones | E19: 1000810776 | F19: Nataly Andrea Maecha Lizarazo | G19: natamahecha23@gmail.com | H19: 3204984051 | I19: Todas | J19: 4 | K19: 4 | L19: 2 | M19: 4 | N19: 4 | O19: 2 | P19: =IF(F19="","",(J19*Parametros!$K$4+K19*Parametros!$K$5+L19*Parametros!$K$6+M19*Parametros!$K$7+N19*Parametros!$K$8+O19*Parametros!$K$9)/Parametros!$B$2) -> 74 | Q19: =IF(F19="","",IF(P19>=Parametros!$B$1,"Aprueba","No aprueba")) -> Aprueba | T19: =IF($Q19="Aprueba",COUNTIF($Q$2:$Q19,"Aprueba"),"") -> 10
A20: =IF(F20="","",ROW()-1) -> 19 | B20: Posgrados | C20: 46211 | D20: Auxiliar gestor de vinculaciones | E20: 1001271946 | F20: Luisa Fernanda Rodríguez Sarmiento | G20: feryantonella13@gmail.com | H20: 3054399778 | I20: Todas | J20: 3 | K20: 5 | L20: 3 | M20: 3 | N20: 4 | O20: 3 | P20: =IF(F20="","",(J20*Parametros!$K$4+K20*Parametros!$K$5+L20*Parametros!$K$6+M20*Parametros!$K$7+N20*Parametros!$K$8+O20*Parametros!$K$9)/Parametros!$B$2) -> 74 | Q20: =IF(F20="","",IF(P20>=Parametros!$B$1,"Aprueba","No aprueba")) -> Aprueba | R20: Presentación personal | T20: =IF($Q20="Aprueba",COUNTIF($Q$2:$Q20,"Aprueba"),"") -> 11
A21: =IF(F21="","",ROW()-1) -> 20 | B21: Posgrados | C21: 46211 | D21: Auxiliar gestor de vinculaciones | E21: 1117813165 | F21: Yedinson Stiven Ramirez Perdómo | G21: kramirezperdomo@gmail.com | H21: 3506517824 | I21: Todas | J21: 5 | K21: 5 | L21: 3 | M21: 5 | N21: 5 | O21: 3 | P21: =IF(F21="","",(J21*Parametros!$K$4+K21*Parametros!$K$5+L21*Parametros!$K$6+M21*Parametros!$K$7+N21*Parametros!$K$8+O21*Parametros!$K$9)/Parametros!$B$2) -> 94 | Q21: =IF(F21="","",IF(P21>=Parametros!$B$1,"Aprueba","No aprueba")) -> Aprueba | T21: =IF($Q21="Aprueba",COUNTIF($Q$2:$Q21,"Aprueba"),"") -> 12
A22: =IF(F22="","",ROW()-1) -> 21 | B22: Posgrados | C22: 46211 | D22: Auxiliar gestor de vinculaciones | E22: 1045686807 | F22: Gisell Del Carmen Cabrera Maldonado | G22: cgisell890@gmail.com | H22: 3017718956 | I22: Todas | J22: 4 | K22: 3 | L22: 5 | M22: 4 | N22: 2 | O22: 2 | P22: =IF(F22="","",(J22*Parametros!$K$4+K22*Parametros!$K$5+L22*Parametros!$K$6+M22*Parametros!$K$7+N22*Parametros!$K$8+O22*Parametros!$K$9)/Parametros!$B$2) -> 58 | Q22: =IF(F22="","",IF(P22>=Parametros!$B$1,"Aprueba","No aprueba")) -> No aprueba | R22: Actitud | T22: =IF($Q22="Aprueba",COUNTIF($Q$2:$Q22,"Aprueba"),"")
A23: =IF(F23="","",ROW()-1) -> 22 | B23: Posgrados | C23: 46211 | D23: Auxiliar gestor de vinculaciones | E23: 1070595836 | F23: Hebert Julián Casilimas Ricardo | G23: julian180703@icloud.com | H23: 3229087879 | I23: Todas | J23: 4 | K23: 4 | L23: 3 | M23: 5 | N23: 5 | O23: 3 | P23: =IF(F23="","",(J23*Parametros!$K$4+K23*Parametros!$K$5+L23*Parametros!$K$6+M23*Parametros!$K$7+N23*Parametros!$K$8+O23*Parametros!$K$9)/Parametros!$B$2) -> 91 | Q23: =IF(F23="","",IF(P23>=Parametros!$B$1,"Aprueba","No aprueba")) -> Aprueba | T23: =IF($Q23="Aprueba",COUNTIF($Q$2:$Q23,"Aprueba"),"") -> 13
A24: =IF(F24="","",ROW()-1) -> 23 | B24: Posgrados | C24: 46211 | D24: Auxiliar gestor de vinculaciones | E24: 1140850536 | F24: Nelvis Mirleth Gutiérrez Orozco | G24: Milrthgutierrez@gmail.com | H24: 3028092333 | I24: Todas | J24: 3 | K24: 3 | L24: 2 | M24: 3 | N24: 3 | O24: 1 | P24: =IF(F24="","",(J24*Parametros!$K$4+K24*Parametros!$K$5+L24*Parametros!$K$6+M24*Parametros!$K$7+N24*Parametros!$K$8+O24*Parametros!$K$9)/Parametros!$B$2) -> 56 | Q24: =IF(F24="","",IF(P24>=Parametros!$B$1,"Aprueba","No aprueba")) -> No aprueba | R24: Actitud | T24: =IF($Q24="Aprueba",COUNTIF($Q$2:$Q24,"Aprueba"),"")
A25: =IF(F25="","",ROW()-1) -> 24 | B25: Posgrados | C25: 46211 | D25: Auxiliar gestor de vinculaciones | E25: 1073709574 | F25: Johan Sebastian Peña Ramos | G25: seebastian0118@gmail.com | H25: 3138749486 | I25: Todas | J25: 4 | K25: 4 | L25: 3 | M25: 3 | N25: 2 | O25: 3 | P25: =IF(F25="","",(J25*Parametros!$K$4+K25*Parametros!$K$5+L25*Parametros!$K$6+M25*Parametros!$K$7+N25*Parametros!$K$8+O25*Parametros!$K$9)/Parametros!$B$2) -> 53 | Q25: =IF(F25="","",IF(P25>=Parametros!$B$1,"Aprueba","No aprueba")) -> No aprueba | T25: =IF($Q25="Aprueba",COUNTIF($Q$2:$Q25,"Aprueba"),"")
A26: =IF(F26="","",ROW()-1) -> 25 | B26: Pregrado Virtual | C26: 46224 | D26: Auxiliar gestor de vinculaciones | E26: 1001187759 | F26: Julian David Jiménez Moreno | G26: Julian.david.jimenez.moreno@gmail.com | H26: 3124832044 | I26: Karen Margarita Puerta | J26: 4 | P26: =IF(F26="","",(J26*Parametros!$K$4+K26*Parametros!$K$5+M26*Parametros!$K$6+N26*Parametros!$K$7+O26*Parametros!$K$8)/Parametros!$B$2) -> 4 | Q26: =IF(F26="","",IF(P26>=Parametros!$B$1,"Aprueba","No aprueba")) -> No aprueba | T26: =IF($Q26="Aprueba",COUNTIF($Q$2:$Q26,"Aprueba"),"")
A27: =IF(F27="","",ROW()-1) -> 26 | B27: Pregrado Virtual | C27: 46224 | D27: Auxiliar gestor de vinculaciones | E27: 1012455544 | F27: Claudia Yadira Suta Torres | G27: claudiasuta029@gmail.com | H27: 3227861878 | I27: Karen Margarita Puerta | J27: 4 | P27: =IF(F27="","",(J27*Parametros!$K$4+K27*Parametros!$K$5+M27*Parametros!$K$6+N27*Parametros!$K$7+O27*Parametros!$K$8)/Parametros!$B$2) -> 4 | Q27: =IF(F27="","",IF(P27>=Parametros!$B$1,"Aprueba","No aprueba")) -> No aprueba | T27: =IF($Q27="Aprueba",COUNTIF($Q$2:$Q27,"Aprueba"),"")
A28: =IF(F28="","",ROW()-1) -> 27 | B28: Pregrado Virtual | C28: 46224 | D28: Auxiliar gestor de vinculaciones | E28: 1001056755 | F28: Cristian Manuel Jiménez Gómez | G28: jimenezsc07@gmail.com | H28: 3123926446 | I28: Karen Margarita Puerta | J28: 3 | P28: =IF(F28="","",(J28*Parametros!$K$4+K28*Parametros!$K$5+M28*Parametros!$K$6+N28*Parametros!$K$7+O28*Parametros!$K$8)/Parametros!$B$2) -> 3 | Q28: =IF(F28="","",IF(P28>=Parametros!$B$1,"Aprueba","No aprueba")) -> No aprueba | T28: =IF($Q28="Aprueba",COUNTIF($Q$2:$Q28,"Aprueba"),"")
A29: =IF(F29="","",ROW()-1) -> 28 | B29: Pregrado Virtual | C29: 46224 | D29: Auxiliar gestor de vinculaciones | E29: 1000328420 | F29: Miguel Ángel Becerra Garcia | G29: Saclaro920@gmail.com | H29: 3223167270 | I29: Karen Margarita Puerta | J29: 3 | P29: =IF(F29="","",(J29*Parametros!$K$4+K29*Parametros!$K$5+M29*Parametros!$K$6+N29*Parametros!$K$7+O29*Parametros!$K$8)/Parametros!$B$2) -> 3 | Q29: =IF(F29="","",IF(P29>=Parametros!$B$1,"Aprueba","No aprueba")) -> No aprueba | T29: =IF($Q29="Aprueba",COUNTIF($Q$2:$Q29,"Aprueba"),"")
A30: =IF(F30="","",ROW()-1) -> 29 | B30: Pregrado Virtual | C30: 46224 | D30: Auxiliar gestor de vinculaciones | E30: 1006118253 | F30: Alex Esteban Angarita Lozano | G30: angarita20162001@gmail.com | H30: 3012268430 | I30: Karen Margarita Puerta | J30: 3 | P30: =IF(F30="","",(J30*Parametros!$K$4+K30*Parametros!$K$5+M30*Parametros!$K$6+N30*Parametros!$K$7+O30*Parametros!$K$8)/Parametros!$B$2) -> 3 | Q30: =IF(F30="","",IF(P30>=Parametros!$B$1,"Aprueba","No aprueba")) -> No aprueba | T30: =IF($Q30="Aprueba",COUNTIF($Q$2:$Q30,"Aprueba"),"")
A31: =IF(F31="","",ROW()-1) -> 30 | B31: Pregrado Virtual | C31: 46224 | D31: Auxiliar gestor de vinculaciones | E31: 1073671475 | F31: Dana Yurleidy Lugo Castro | G31: danalugo12345@gmail.com | H31: 3147647259 | I31: Karen Margarita Puerta | J31: 4 | P31: =IF(F31="","",(J31*Parametros!$K$4+K31*Parametros!$K$5+M31*Parametros!$K$6+N31*Parametros!$K$7+O31*Parametros!$K$8)/Parametros!$B$2) -> 4 | Q31: =IF(F31="","",IF(P31>=Parametros!$B$1,"Aprueba","No aprueba")) -> No aprueba | T31: =IF($Q31="Aprueba",COUNTIF($Q$2:$Q31,"Aprueba"),"")
A32: =IF(F32="","",ROW()-1) -> 31 | B32: Pregrado Virtual | C32: 46224 | D32: Auxiliar gestor de vinculaciones | E32: 1013670551 | F32: Andersson Stiven Lozano Martinez | G32: andersson19892014@gmail.com | H32: 3244759449 | I32: Karen Margarita Puerta | J32: 4 | N32: (empty) | P32: =IF(F32="","",(J32*Parametros!$K$4+K32*Parametros!$K$5+M32*Parametros!$K$6+N32*Parametros!$K$7+O32*Parametros!$K$8)/Parametros!$B$2) -> #VALUE! | Q32: =IF(F32="","",IF(P32>=Parametros!$B$1,"Aprueba","No aprueba")) -> #VALUE! | T32: =IF($Q32="Aprueba",COUNTIF($Q$2:$Q32,"Aprueba"),"") -> #VALUE!
A33: =IF(F33="","",ROW()-1) -> 32 | B33: Pregrado Virtual | C33: 46224 | D33: Auxiliar gestor de vinculaciones | E33: 1007343398 | F33: Duvan Alejandro Díaz Landinez | G33: Alejithodiax@gmail.com | H33: 3026595949 | I33: Karen Margarita Puerta | J33: 4 | P33: =IF(F33="","",(J33*Parametros!$K$4+K33*Parametros!$K$5+M33*Parametros!$K$6+N33*Parametros!$K$7+O33*Parametros!$K$8)/Parametros!$B$2) -> 4 | Q33: =IF(F33="","",IF(P33>=Parametros!$B$1,"Aprueba","No aprueba")) -> No aprueba | T33: =IF($Q33="Aprueba",COUNTIF($Q$2:$Q33,"Aprueba"),"")
A34: =IF(F34="","",ROW()-1) -> 33 | B34: Pregrado Virtual | C34: 46224 | D34: Auxiliar gestor de vinculaciones | E34: 1007845676 | F34: Brandon Stiven Garces Arcos | G34: Brandongarces2@gmail.com | H34: 3223299162 | I34: Karen Margarita Puerta | J34: 4 | P34: =IF(F34="","",(J34*Parametros!$K$4+K34*Parametros!$K$5+M34*Parametros!$K$6+N34*Parametros!$K$7+O34*Parametros!$K$8)/Parametros!$B$2) -> 4 | Q34: =IF(F34="","",IF(P34>=Parametros!$B$1,"Aprueba","No aprueba")) -> No aprueba | T34: =IF($Q34="Aprueba",COUNTIF($Q$2:$Q34,"Aprueba"),"")
A35: =IF(F35="","",ROW()-1) -> 34 | B35: Pregrado Virtual | C35: 46224 | D35: Auxiliar gestor de vinculaciones | E35: 1033772502 | F35: Juan Sebastian Acevedo Salazar | G35: juansevedo02@gmail.com | H35: 3025718737 | I35: Karen Margarita Puerta | J35: 4 | P35: =IF(F35="","",(J35*Parametros!$K$4+K35*Parametros!$K$5+M35*Parametros!$K$6+N35*Parametros!$K$7+O35*Parametros!$K$8)/Parametros!$B$2) -> 4 | Q35: =IF(F35="","",IF(P35>=Parametros!$B$1,"Aprueba","No aprueba")) -> No aprueba | T35: =IF($Q35="Aprueba",COUNTIF($Q$2:$Q35,"Aprueba"),"")
A36: =IF(F36="","",ROW()-1) | P36: =IF(F36="","",(J36*Parametros!$K$4+K36*Parametros!$K$5+M36*Parametros!$K$6+N36*Parametros!$K$7+O36*Parametros!$K$8)/Parametros!$B$2) | Q36: =IF(F36="","",IF(P36>=Parametros!$B$1,"Aprueba","No aprueba")) | T36: =IF($Q36="Aprueba",COUNTIF($Q$2:$Q36,"Aprueba"),"")
A37: =IF(F37="","",ROW()-1) | P37: =IF(F37="","",(J37*Parametros!$K$4+K37*Parametros!$K$5+M37*Parametros!$K$6+N37*Parametros!$K$7+O37*Parametros!$K$8)/Parametros!$B$2) | Q37: =IF(F37="","",IF(P37>=Parametros!$B$1,"Aprueba","No aprueba")) | T37: =IF($Q37="Aprueba",COUNTIF($Q$2:$Q37,"Aprueba"),"")
A38: =IF(F38="","",ROW()-1) | P38: =IF(F38="","",(J38*Parametros!$K$4+K38*Parametros!$K$5+M38*Parametros!$K$6+N38*Parametros!$K$7+O38*Parametros!$K$8)/Parametros!$B$2) | Q38: =IF(F38="","",IF(P38>=Parametros!$B$1,"Aprueba","No aprueba")) | T38: =IF($Q38="Aprueba",COUNTIF($Q$2:$Q38,"Aprueba"),"")
A39: =IF(F39="","",ROW()-1) | P39: =IF(F39="","",(J39*Parametros!$K$4+K39*Parametros!$K$5+M39*Parametros!$K$6+N39*Parametros!$K$7+O39*Parametros!$K$8)/Parametros!$B$2) | Q39: =IF(F39="","",IF(P39>=Parametros!$B$1,"Aprueba","No aprueba")) | T39: =IF($Q39="Aprueba",COUNTIF($Q$2:$Q39,"Aprueba"),"")
A40: =IF(F40="","",ROW()-1) | P40: =IF(F40="","",(J40*Parametros!$K$4+K40*Parametros!$K$5+M40*Parametros!$K$6+N40*Parametros!$K$7+O40*Parametros!$K$8)/Parametros!$B$2) | Q40: =IF(F40="","",IF(P40>=Parametros!$B$1,"Aprueba","No aprueba")) | T40: =IF($Q40="Aprueba",COUNTIF($Q$2:$Q40,"Aprueba"),"")
...

Sheet Resumen
A1: RESUMEN DE INGRESOS A FORMACIÓN (OJT)
A3: Total de personas registradas | B3: =COUNT(Registro!A2:A96) -> 34
A4: Total aprobados | B4: =COUNTIF(Registro!Q2:Q96,"Aprueba") -> 13
A5: Total no aprobados | B5: =COUNTIF(Registro!Q2:Q96,"No aprueba") -> 20
A6: % de aprobación | B6: =IFERROR(B4/B3,"") -> 0.38235294
A7: Nota promedio general | B7: =IFERROR(AVERAGE(Registro!P2:P96),"")
A8: Total retirados | B8: =COUNTIF(Registro!#REF!,"Retirado") -> #REF!
A9: Total en formación | B9: =COUNTIF(Registro!#REF!,"En formación") -> #REF!
A12: REGISTROS POR CAMPAÑA
A13: Campaña | B13: N° personas | C13: N° aprobados | D13: % aprobación
A14: Pregrado Virtual | B14: =COUNTIF(Registro!$B$2:$B$96,A14) -> 10 | C14: =COUNTIFS(Registro!$B$2:$B$96,A14,Registro!$Q$2:$Q$96,"Aprueba") -> 0 | D14: =IFERROR(C14/B14,"") -> 0
A15: Pregrado Presencial | B15: =COUNTIF(Registro!$B$2:$B$96,A15) -> 0 | C15: =COUNTIFS(Registro!$B$2:$B$96,A15,Registro!$Q$2:$Q$96,"Aprueba") -> 0 | D15: =IFERROR(C15/B15,"")
A16: Posgrados | B16: =COUNTIF(Registro!$B$2:$B$96,A16) -> 24 | C16: =COUNTIFS(Registro!$B$2:$B$96,A16,Registro!$Q$2:$Q$96,"Aprueba") -> 13 | D16: =IFERROR(C16/B16,"") -> 0.54166667
B17: =COUNTIF(Registro!$B$2:$B$96,A17) -> 0 | C17: =COUNTIFS(Registro!$B$2:$B$96,A17,Registro!$Q$2:$Q$96,"Aprueba") -> 0 | D17: =IFERROR(C17/B17,"")
B18: =COUNTIF(Registro!$B$2:$B$96,A18) -> 0 | C18: =COUNTIFS(Registro!$B$2:$B$96,A18,Registro!$Q$2:$Q$96,"Aprueba") -> 0 | D18: =IFERROR(C18/B18,"")
A21: REGISTROS POR FORMADOR
A22: Formador | B22: N° personas | C22: N° aprobados | D22: Nota promedio
A23: Karen Margarita Puerta | B23: =COUNTIF(Registro!$I$2:$I$96,A23) -> 10 | C23: =COUNTIFS(Registro!$I$2:$I$96,A23,Registro!$Q$2:$Q$96,"Aprueba") -> 0 | D23: =IFERROR(AVERAGEIF(Registro!$I$2:$I$96,A23,Registro!$P$2:$P$96),"")
A24: Mayra Sofia Sanchez | B24: =COUNTIF(Registro!$I$2:$I$96,A24) -> 0 | C24: =COUNTIFS(Registro!$I$2:$I$96,A24,Registro!$Q$2:$Q$96,"Aprueba") -> 0 | D24: =IFERROR(AVERAGEIF(Registro!$I$2:$I$96,A24,Registro!$P$2:$P$96),"")
A25: Monica Sanchez | B25: =COUNTIF(Registro!$I$2:$I$96,A25) -> 0 | C25: =COUNTIFS(Registro!$I$2:$I$96,A25,Registro!$Q$2:$Q$96,"Aprueba") -> 0 | D25: =IFERROR(AVERAGEIF(Registro!$I$2:$I$96,A25,Registro!$P$2:$P$96),"")
A26: Todas | B26: =COUNTIF(Registro!$I$2:$I$96,A26) -> 0 | C26: =COUNTIFS(Registro!$I$2:$I$96,A26,Registro!$Q$2:$Q$96,"Aprueba") -> 0

Sheet Parametros
A1: Nota minima para aprobar | B1: 70 | C1: (edita este valor para ajustar el umbral de aprobacion)
A2: Escala de calificación (máximo por ítem) | B2: 5 | C2: (cada ítem se califica de 1 a 5)
D3: CAMPAÑA | E3: CARGO | F3: FORMADOR | G3: ESTADO DEL PROCESO | H3: APRUEBA | J3: ITEM DE EVALUACIÓN | K3: PESO %
D4: Pregrado Virtual | E4: Gestor vinculaciones Junior | F4: Karen Margarita Puerta | G4: En formación | H4: Aprueba | J4: Presentación personal | K4: 5
D5: Pregrado Presencial | E5: Gestor vinculaciones Senior | F5: Mayra Sofia Sanchez | G5: OJT | H5: No aprueba | J5: Participación y puntualidad | K5: 10
D6: Posgrados | E6: Auxiliar gestor de vinculaciones | F6: Monica Sanchez | G6: Retirado | J6: Evaluación conocimiento & role play | K6: 10
D7: Comercial B2B | F7: Todas | J7: Simulación con IA | K7: 20
J8: Evaluación final (clínica de ventas) | K8: 50
J9: Evaluación conocimiento (Día 2) | K9: 5
D12: Escala de evaluación
D14: 90–100 = 5
D15: 80–89 = 4
D16: 70–79 = 3
D17: 60–69 = 2
D18: 0–59 = 1

Sheet OJT
A1: No. DOCUMENTO | B1: NOMBRE COMPLETO | C1: CORREO ELECTRÓNICO | D1: TELÉFONO MÓVIL | E1: FECHA DE INGRESO A FORMACIÓN | F1: CAMPAÑA | G1: NOTA FINAL | H1: APRUEBA
A2: =IFERROR(INDEX(Registro!$E$2:$E$500,MATCH(1,Registro!$T$2:$T$500,0)),"") -> 1193156026 | B2: =IFERROR(INDEX(Registro!$F$2:$F$500,MATCH(1,Registro!$T$2:$T$500,0)),"") -> Sara Isabel Molina Sánchez | C2: =IFERROR(INDEX(Registro!$G$2:$G$500,MATCH(1,Registro!$T$2:$T$500,0)),"") -> Molinasara453@gmail.com | D2: =IFERROR(INDEX(Registro!$H$2:$H$500,MATCH(1,Registro!$T$2:$T$500,0)),"") -> 3245742876 | E2: =IFERROR(INDEX(Registro!$C$2:$C$500,MATCH(1,Registro!$T$2:$T$500,0)),"") -> 46204 | F2: =IFERROR(INDEX(Registro!$B$2:$B$500,MATCH(1,Registro!$T$2:$T$500,0)),"") -> Posgrados | G2: =IFERROR(INDEX(Registro!$P$2:$P$500,MATCH(1,Registro!$T$2:$T$500,0)),"") -> 72 | H2: =IFERROR(INDEX(Registro!$Q$2:$Q$500,MATCH(1,Registro!$T$2:$T$500,0)),"") -> Aprueba
A3: =IFERROR(INDEX(Registro!$E$2:$E$500,MATCH(2,Registro!$T$2:$T$500,0)),"") -> 1016001652 | B3: =IFERROR(INDEX(Registro!$F$2:$F$500,MATCH(2,Registro!$T$2:$T$500,0)),"") -> Helen Sofia Calderon Camelo | C3: =IFERROR(INDEX(Registro!$G$2:$G$500,MATCH(2,Registro!$T$2:$T$500,0)),"") -> helencalderon910@gmail.com | D3: =IFERROR(INDEX(Registro!$H$2:$H$500,MATCH(2,Registro!$T$2:$T$500,0)),"") -> ‪3239227093‬ | E3: =IFERROR(INDEX(Registro!$C$2:$C$500,MATCH(2,Registro!$T$2:$T$500,0)),"") -> 46204 | F3: =IFERROR(INDEX(Registro!$B$2:$B$500,MATCH(2,Registro!$T$2:$T$500,0)),"") -> Posgrados | G3: =IFERROR(INDEX(Registro!$P$2:$P$500,MATCH(2,Registro!$T$2:$T$500,0)),"") -> 70 | H3: =IFERROR(INDEX(Registro!$Q$2:$Q$500,MATCH(2,Registro!$T$2:$T$500,0)),"") -> Aprueba
A4: =IFERROR(INDEX(Registro!$E$2:$E$500,MATCH(3,Registro!$T$2:$T$500,0)),"") -> 1001314657 | B4: =IFERROR(INDEX(Registro!$F$2:$F$500,MATCH(3,Registro!$T$2:$T$500,0)),"") -> Thomas Bernardo Fernandez Laverde | C4: =IFERROR(INDEX(Registro!$G$2:$G$500,MATCH(3,Registro!$T$2:$T$500,0)),"") -> tfernandezlaverde@gmail.com | D4: =IFERROR(INDEX(Registro!$H$2:$H$500,MATCH(3,Registro!$T$2:$T$500,0)),"") -> 3103798566 | E4: =IFERROR(INDEX(Registro!$C$2:$C$500,MATCH(3,Registro!$T$2:$T$500,0)),"") -> 46204 | F4: =IFERROR(INDEX(Registro!$B$2:$B$500,MATCH(3,Registro!$T$2:$T$500,0)),"") -> Posgrados | G4: =IFERROR(INDEX(Registro!$P$2:$P$500,MATCH(3,Registro!$T$2:$T$500,0)),"") -> 72 | H4: =IFERROR(INDEX(Registro!$Q$2:$Q$500,MATCH(3,Registro!$T$2:$T$500,0)),"") -> Aprueba
A5: =IFERROR(INDEX(Registro!$E$2:$E$500,MATCH(4,Registro!$T$2:$T$500,0)),"") -> 1033096735 | B5: =IFERROR(INDEX(Registro!$F$2:$F$500,MATCH(4,Registro!$T$2:$T$500,0)),"") -> Pablo Steven Ochoa Rodriguez | C5: =IFERROR(INDEX(Registro!$G$2:$G$500,MATCH(4,Registro!$T$2:$T$500,0)),"") -> Pablorodriguez8q@gmail.com | D5: =IFERROR(INDEX(Registro!$H$2:$H$500,MATCH(4,Registro!$T$2:$T$500,0)),"") -> 3196588439 | E5: =IFERROR(INDEX(Registro!$C$2:$C$500,MATCH(4,Registro!$T$2:$T$500,0)),"") -> 46204 | F5: =IFERROR(INDEX(Registro!$B$2:$B$500,MATCH(4,Registro!$T$2:$T$500,0)),"") -> Posgrados | G5: =IFERROR(INDEX(Registro!$P$2:$P$500,MATCH(4,Registro!$T$2:$T$500,0)),"") -> 81 | H5: =IFERROR(INDEX(Registro!$Q$2:$Q$500,MATCH(4,Registro!$T$2:$T$500,0)),"") -> Aprueba
A6: =IFERROR(INDEX(Registro!$E$2:$E$500,MATCH(5,Registro!$T$2:$T$500,0)),"") -> 1004961429 | B6: =IFERROR(INDEX(Registro!$F$2:$F$500,MATCH(5,Registro!$T$2:$T$500,0)),"") -> Jhon Stiven Marin Valencia | C6: =IFERROR(INDEX(Registro!$G$2:$G$500,MATCH(5,Registro!$T$2:$T$500,0)),"") -> jhonstivenmarin02@gmail.com | D6: =IFERROR(INDEX(Registro!$H$2:$H$500,MATCH(5,Registro!$T$2:$T$500,0)),"") -> 3219466413 | E6: =IFERROR(INDEX(Registro!$C$2:$C$500,MATCH(5,Registro!$T$2:$T$500,0)),"") -> 46204 | F6: =IFERROR(INDEX(Registro!$B$2:$B$500,MATCH(5,Registro!$T$2:$T$500,0)),"") -> Posgrados | G6: =IFERROR(INDEX(Registro!$P$2:$P$500,MATCH(5,Registro!$T$2:$T$500,0)),"") -> 73 | H6: =IFERROR(INDEX(Registro!$Q$2:$Q$500,MATCH(5,Registro!$T$2:$T$500,0)),"") -> Aprueba
A7: =IFERROR(INDEX(Registro!$E$2:$E$500,MATCH(6,Registro!$T$2:$T$500,0)),"") -> 53121281 | B7: =IFERROR(INDEX(Registro!$F$2:$F$500,MATCH(6,Registro!$T$2:$T$500,0)),"") -> Yulieth Paola Rodriguez Cañon | C7: =IFERROR(INDEX(Registro!$G$2:$G$500,MATCH(6,Registro!$T$2:$T$500,0)),"") -> ypaolarodriguez14@gmail.com | D7: =IFERROR(INDEX(Registro!$H$2:$H$500,MATCH(6,Registro!$T$2:$T$500,0)),"") -> 3112142736 | E7: =IFERROR(INDEX(Registro!$C$2:$C$500,MATCH(6,Registro!$T$2:$T$500,0)),"") -> 46204 | F7: =IFERROR(INDEX(Registro!$B$2:$B$500,MATCH(6,Registro!$T$2:$T$500,0)),"") -> Posgrados | G7: =IFERROR(INDEX(Registro!$P$2:$P$500,MATCH(6,Registro!$T$2:$T$500,0)),"") -> 78 | H7: =IFERROR(INDEX(Registro!$Q$2:$Q$500,MATCH(6,Registro!$T$2:$T$500,0)),"") -> Aprueba
A8: =IFERROR(INDEX(Registro!$E$2:$E$500,MATCH(7,Registro!$T$2:$T$500,0)),"") -> 1024585365 | B8: =IFERROR(INDEX(Registro!$F$2:$F$500,MATCH(7,Registro!$T$2:$T$500,0)),"") -> Cristian David Celis Garcia | C8: =IFERROR(INDEX(Registro!$G$2:$G$500,MATCH(7,Registro!$T$2:$T$500,0)),"") -> cristianceliss9719@gmail.com | D8: =IFERROR(INDEX(Registro!$H$2:$H$500,MATCH(7,Registro!$T$2:$T$500,0)),"") -> 3216686201 | E8: =IFERROR(INDEX(Registro!$C$2:$C$500,MATCH(7,Registro!$T$2:$T$500,0)),"") -> 46211 | F8: =IFERROR(INDEX(Registro!$B$2:$B$500,MATCH(7,Registro!$T$2:$T$500,0)),"") -> Posgrados | G8: =IFERROR(INDEX(Registro!$P$2:$P$500,MATCH(7,Registro!$T$2:$T$500,0)),"") -> 73 | H8: =IFERROR(INDEX(Registro!$Q$2:$Q$500,MATCH(7,Registro!$T$2:$T$500,0)),"") -> Aprueba
A9: =IFERROR(INDEX(Registro!$E$2:$E$500,MATCH(8,Registro!$T$2:$T$500,0)),"") -> 1000547797 | B9: =IFERROR(INDEX(Registro!$F$2:$F$500,MATCH(8,Registro!$T$2:$T$500,0)),"") -> Kamy Lizeth Rios Gomez | C9: =IFERROR(INDEX(Registro!$G$2:$G$500,MATCH(8,Registro!$T$2:$T$500,0)),"") -> riosgomezkamy@gmail.com | D9: =IFERROR(INDEX(Registro!$H$2:$H$500,MATCH(8,Registro!$T$2:$T$500,0)),"") -> 3112534635 | E9: =IFERROR(INDEX(Registro!$C$2:$C$500,MATCH(8,Registro!$T$2:$T$500,0)),"") -> 46211 | F9: =IFERROR(INDEX(Registro!$B$2:$B$500,MATCH(8,Registro!$T$2:$T$500,0)),"") -> Posgrados | G9: =IFERROR(INDEX(Registro!$P$2:$P$500,MATCH(8,Registro!$T$2:$T$500,0)),"") -> 90 | H9: =IFERROR(INDEX(Registro!$Q$2:$Q$500,MATCH(8,Registro!$T$2:$T$500,0)),"") -> Aprueba
A10: =IFERROR(INDEX(Registro!$E$2:$E$500,MATCH(9,Registro!$T$2:$T$500,0)),"") -> 1023867138 | B10: =IFERROR(INDEX(Registro!$F$2:$F$500,MATCH(9,Registro!$T$2:$T$500,0)),"") -> Yisell Dayana Castro González | C10: =IFERROR(INDEX(Registro!$G$2:$G$500,MATCH(9,Registro!$T$2:$T$500,0)),"") -> Gonzalezdayanna730@gmail.com | D10: =IFERROR(INDEX(Registro!$H$2:$H$500,MATCH(9,Registro!$T$2:$T$500,0)),"") -> 3143600585 | E10: =IFERROR(INDEX(Registro!$C$2:$C$500,MATCH(9,Registro!$T$2:$T$500,0)),"") -> 46211 | F10: =IFERROR(INDEX(Registro!$B$2:$B$500,MATCH(9,Registro!$T$2:$T$500,0)),"") -> Posgrados | G10: =IFERROR(INDEX(Registro!$P$2:$P$500,MATCH(9,Registro!$T$2:$T$500,0)),"") -> 72 | H10: =IFERROR(INDEX(Registro!$Q$2:$Q$500,MATCH(9,Registro!$T$2:$T$500,0)),"") -> Aprueba
A11: =IFERROR(INDEX(Registro!$E$2:$E$500,MATCH(10,Registro!$T$2:$T$500,0)),"") -> 1000810776 | B11: =IFERROR(INDEX(Registro!$F$2:$F$500,MATCH(10,Registro!$T$2:$T$500,0)),"") -> Nataly Andrea Maecha Lizarazo | C11: =IFERROR(INDEX(Registro!$G$2:$G$500,MATCH(10,Registro!$T$2:$T$500,0)),"") -> natamahecha23@gmail.com | D11: =IFERROR(INDEX(Registro!$H$2:$H$500,MATCH(10,Registro!$T$2:$T$500,0)),"") -> 3204984051 | E11: =IFERROR(INDEX(Registro!$C$2:$C$500,MATCH(10,Registro!$T$2:$T$500,0)),"") -> 46211 | F11: =IFERROR(INDEX(Registro!$B$2:$B$500,MATCH(10,Registro!$T$2:$T$500,0)),"") -> Posgrados | G11: =IFERROR(INDEX(Registro!$P$2:$P$500,MATCH(10,Registro!$T$2:$T$500,0)),"") -> 74 | H11: =IFERROR(INDEX(Registro!$Q$2:$Q$500,MATCH(10,Registro!$T$2:$T$500,0)),"") -> Aprueba
A12: =IFERROR(INDEX(Registro!$E$2:$E$500,MATCH(11,Registro!$T$2:$T$500,0)),"") -> 1001271946 | B12: =IFERROR(INDEX(Registro!$F$2:$F$500,MATCH(11,Registro!$T$2:$T$500,0)),"") -> Luisa Fernanda Rodríguez Sarmiento | C12: =IFERROR(INDEX(Registro!$G$2:$G$500,MATCH(11,Registro!$T$2:$T$500,0)),"") -> feryantonella13@gmail.com | D12: =IFERROR(INDEX(Registro!$H$2:$H$500,MATCH(11,Registro!$T$2:$T$500,0)),"") -> 3054399778 | E12: =IFERROR(INDEX(Registro!$C$2:$C$500,MATCH(11,Registro!$T$2:$T$500,0)),"") -> 46211 | F12: =IFERROR(INDEX(Registro!$B$2:$B$500,MATCH(11,Registro!$T$2:$T$500,0)),"") -> Posgrados | G12: =IFERROR(INDEX(Registro!$P$2:$P$500,MATCH(11,Registro!$T$2:$T$500,0)),"") -> 74 | H12: =IFERROR(INDEX(Registro!$Q$2:$Q$500,MATCH(11,Registro!$T$2:$T$500,0)),"") -> Aprueba
A13: =IFERROR(INDEX(Registro!$E$2:$E$500,MATCH(12,Registro!$T$2:$T$500,0)),"") -> 1117813165 | B13: =IFERROR(INDEX(Registro!$F$2:$F$500,MATCH(12,Registro!$T$2:$T$500,0)),"") -> Yedinson Stiven Ramirez Perdómo | C13: =IFERROR(INDEX(Registro!$G$2:$G$500,MATCH(12,Registro!$T$2:$T$500,0)),"") -> kramirezperdomo@gmail.com | D13: =IFERROR(INDEX(Registro!$H$2:$H$500,MATCH(12,Registro!$T$2:$T$500,0)),"") -> 3506517824 | E13: =IFERROR(INDEX(Registro!$C$2:$C$500,MATCH(12,Registro!$T$2:$T$500,0)),"") -> 46211 | F13: =IFERROR(INDEX(Registro!$B$2:$B$500,MATCH(12,Registro!$T$2:$T$500,0)),"") -> Posgrados | G13: =IFERROR(INDEX(Registro!$P$2:$P$500,MATCH(12,Registro!$T$2:$T$500,0)),"") -> 94 | H13: =IFERROR(INDEX(Registro!$Q$2:$Q$500,MATCH(12,Registro!$T$2:$T$500,0)),"") -> Aprueba
A14: =IFERROR(INDEX(Registro!$E$2:$E$500,MATCH(13,Registro!$T$2:$T$500,0)),"") -> 1070595836 | B14: =IFERROR(INDEX(Registro!$F$2:$F$500,MATCH(13,Registro!$T$2:$T$500,0)),"") -> Hebert Julián Casilimas Ricardo | C14: =IFERROR(INDEX(Registro!$G$2:$G$500,MATCH(13,Registro!$T$2:$T$500,0)),"") -> julian180703@icloud.com | D14: =IFERROR(INDEX(Registro!$H$2:$H$500,MATCH(13,Registro!$T$2:$T$500,0)),"") -> 3229087879 | E14: =IFERROR(INDEX(Registro!$C$2:$C$500,MATCH(13,Registro!$T$2:$T$500,0)),"") -> 46211 | F14: =IFERROR(INDEX(Registro!$B$2:$B$500,MATCH(13,Registro!$T$2:$T$500,0)),"") -> Posgrados | G14: =IFERROR(INDEX(Registro!$P$2:$P$500,MATCH(13,Registro!$T$2:$T$500,0)),"") -> 91 | H14: =IFERROR(INDEX(Registro!$Q$2:$Q$500,MATCH(13,Registro!$T$2:$T$500,0)),"") -> Aprueba
B15: =IFERROR(INDEX(Registro!$F$2:$F$500,MATCH(14,Registro!$T$2:$T$500,0)),"") | C15: =IFERROR(INDEX(Registro!$G$2:$G$500,MATCH(14,Registro!$T$2:$T$500,0)),"") | D15: =IFERROR(INDEX(Registro!$H$2:$H$500,MATCH(14,Registro!$T$2:$T$500,0)),"") | E15: =IFERROR(INDEX(Registro!$C$2:$C$500,MATCH(14,Registro!$T$2:$T$500,0)),"") | F15: =IFERROR(INDEX(Registro!$B$2:$B$500,MATCH(14,Registro!$T$2:$T$500,0)),"") | G15: =IFERROR(INDEX(Registro!$P$2:$P$500,MATCH(14,Registro!$T$2:$T$500,0)),"") | H15: =IFERROR(INDEX(Registro!$Q$2:$Q$500,MATCH(14,Registro!$T$2:$T$500,0)),"")
A16: =IFERROR(INDEX(Registro!$E$2:$E$500,MATCH(15,Registro!$T$2:$T$500,0)),"") | B16: =IFERROR(INDEX(Registro!$F$2:$F$500,MATCH(15,Registro!$T$2:$T$500,0)),"") | C16: =IFERROR(INDEX(Registro!$G$2:$G$500,MATCH(15,Registro!$T$2:$T$500,0)),"") | D16: =IFERROR(INDEX(Registro!$H$2:$H$500,MATCH(15,Registro!$T$2:$T$500,0)),"") | E16: =IFERROR(INDEX(Registro!$C$2:$C$500,MATCH(15,Registro!$T$2:$T$500,0)),"") | F16: =IFERROR(INDEX(Registro!$B$2:$B$500,MATCH(15,Registro!$T$2:$T$500,0)),"") | G16: =IFERROR(INDEX(Registro!$P$2:$P$500,MATCH(15,Registro!$T$2:$T$500,0)),"") | H16: =IFERROR(INDEX(Registro!$Q$2:$Q$500,MATCH(15,Registro!$T$2:$T$500,0)),"")
A17: =IFERROR(INDEX(Registro!$E$2:$E$500,MATCH(16,Registro!$T$2:$T$500,0)),"") | B17: =IFERROR(INDEX(Registro!$F$2:$F$500,MATCH(16,Registro!$T$2:$T$500,0)),"") | C17: =IFERROR(INDEX(Registro!$G$2:$G$500,MATCH(16,Registro!$T$2:$T$500,0)),"") | D17: =IFERROR(INDEX(Registro!$H$2:$H$500,MATCH(16,Registro!$T$2:$T$500,0)),"") | E17: =IFERROR(INDEX(Registro!$C$2:$C$500,MATCH(16,Registro!$T$2:$T$500,0)),"") | F17: =IFERROR(INDEX(Registro!$B$2:$B$500,MATCH(16,Registro!$T$2:$T$500,0)),"") | G17: =IFERROR(INDEX(Registro!$P$2:$P$500,MATCH(16,Registro!$T$2:$T$500,0)),"") | H17: =IFERROR(INDEX(Registro!$Q$2:$Q$500,MATCH(16,Registro!$T$2:$T$500,0)),"")
A18: =IFERROR(INDEX(Registro!$E$2:$E$500,MATCH(17,Registro!$T$2:$T$500,0)),"") | B18: =IFERROR(INDEX(Registro!$F$2:$F$500,MATCH(17,Registro!$T$2:$T$500,0)),"") | C18: =IFERROR(INDEX(Registro!$G$2:$G$500,MATCH(17,Registro!$T$2:$T$500,0)),"") | D18: =IFERROR(INDEX(Registro!$H$2:$H$500,MATCH(17,Registro!$T$2:$T$500,0)),"") | E18: =IFERROR(INDEX(Registro!$C$2:$C$500,MATCH(17,Registro!$T$2:$T$500,0)),"") | F18: =IFERROR(INDEX(Registro!$B$2:$B$500,MATCH(17,Registro!$T$2:$T$500,0)),"") | G18: =IFERROR(INDEX(Registro!$P$2:$P$500,MATCH(17,Registro!$T$2:$T$500,0)),"") | H18: =IFERROR(INDEX(Registro!$Q$2:$Q$500,MATCH(17,Registro!$T$2:$T$500,0)),"")
A19: =IFERROR(INDEX(Registro!$E$2:$E$500,MATCH(18,Registro!$T$2:$T$500,0)),"") | B19: =IFERROR(INDEX(Registro!$F$2:$F$500,MATCH(18,Registro!$T$2:$T$500,0)),"") | C19: =IFERROR(INDEX(Registro!$G$2:$G$500,MATCH(18,Registro!$T$2:$T$500,0)),"") | D19: =IFERROR(INDEX(Registro!$H$2:$H$500,MATCH(18,Registro!$T$2:$T$500,0)),"") | E19: =IFERROR(INDEX(Registro!$C$2:$C$500,MATCH(18,Registro!$T$2:$T$500,0)),"") | F19: =IFERROR(INDEX(Registro!$B$2:$B$500,MATCH(18,Registro!$T$2:$T$500,0)),"") | G19: =IFERROR(INDEX(Registro!$P$2:$P$500,MATCH(18,Registro!$T$2:$T$500,0)),"") | H19: =IFERROR(INDEX(Registro!$Q$2:$Q$500,MATCH(18,Registro!$T$2:$T$500,0)),"")
A20: =IFERROR(INDEX(Registro!$E$2:$E$500,MATCH(19,Registro!$T$2:$T$500,0)),"") | B20: =IFERROR(INDEX(Registro!$F$2:$F$500,MATCH(19,Registro!$T$2:$T$500,0)),"") | C20: =IFERROR(INDEX(Registro!$G$2:$G$500,MATCH(19,Registro!$T$2:$T$500,0)),"") | D20: =IFERROR(INDEX(Registro!$H$2:$H$500,MATCH(19,Registro!$T$2:$T$500,0)),"") | E20: =IFERROR(INDEX(Registro!$C$2:$C$500,MATCH(19,Registro!$T$2:$T$500,0)),"") | F20: =IFERROR(INDEX(Registro!$B$2:$B$500,MATCH(19,Registro!$T$2:$T$500,0)),"") | G20: =IFERROR(INDEX(Registro!$P$2:$P$500,MATCH(19,Registro!$T$2:$T$500,0)),"") | H20: =IFERROR(INDEX(Registro!$Q$2:$Q$500,MATCH(19,Registro!$T$2:$T$500,0)),"")
A21: =IFERROR(INDEX(Registro!$E$2:$E$500,MATCH(20,Registro!$T$2:$T$500,0)),"") | B21: =IFERROR(INDEX(Registro!$F$2:$F$500,MATCH(20,Registro!$T$2:$T$500,0)),"") | C21: =IFERROR(INDEX(Registro!$G$2:$G$500,MATCH(20,Registro!$T$2:$T$500,0)),"") | D21: =IFERROR(INDEX(Registro!$H$2:$H$500,MATCH(20,Registro!$T$2:$T$500,0)),"") | E21: =IFERROR(INDEX(Registro!$C$2:$C$500,MATCH(20,Registro!$T$2:$T$500,0)),"") | F21: =IFERROR(INDEX(Registro!$B$2:$B$500,MATCH(20,Registro!$T$2:$T$500,0)),"") | G21: =IFERROR(INDEX(Registro!$P$2:$P$500,MATCH(20,Registro!$T$2:$T$500,0)),"") | H21: =IFERROR(INDEX(Registro!$Q$2:$Q$500,MATCH(20,Registro!$T$2:$T$500,0)),"")
A22: =IFERROR(INDEX(Registro!$E$2:$E$500,MATCH(21,Registro!$T$2:$T$500,0)),"") | B22: =IFERROR(INDEX(Registro!$F$2:$F$500,MATCH(21,Registro!$T$2:$T$500,0)),"") | C22: =IFERROR(INDEX(Registro!$G$2:$G$500,MATCH(21,Registro!$T$2:$T$500,0)),"") | D22: =IFERROR(INDEX(Registro!$H$2:$H$500,MATCH(21,Registro!$T$2:$T$500,0)),"") | E22: =IFERROR(INDEX(Registro!$C$2:$C$500,MATCH(21,Registro!$T$2:$T$500,0)),"") | F22: =IFERROR(INDEX(Registro!$B$2:$B$500,MATCH(21,Registro!$T$2:$T$500,0)),"") | G22: =IFERROR(INDEX(Registro!$P$2:$P$500,MATCH(21,Registro!$T$2:$T$500,0)),"") | H22: =IFERROR(INDEX(Registro!$Q$2:$Q$500,MATCH(21,Registro!$T$2:$T$500,0)),"")
A23: =IFERROR(INDEX(Registro!$E$2:$E$500,MATCH(22,Registro!$T$2:$T$500,0)),"") | B23: =IFERROR(INDEX(Registro!$F$2:$F$500,MATCH(22,Registro!$T$2:$T$500,0)),"") | C23: =IFERROR(INDEX(Registro!$G$2:$G$500,MATCH(22,Registro!$T$2:$T$500,0)),"") | D23: =IFERROR(INDEX(Registro!$H$2:$H$500,MATCH(22,Registro!$T$2:$T$500,0)),"") | E23: =IFERROR(INDEX(Registro!$C$2:$C$500,MATCH(22,Registro!$T$2:$T$500,0)),"") | F23: =IFERROR(INDEX(Registro!$B$2:$B$500,MATCH(22,Registro!$T$2:$T$500,0)),"") | G23: =IFERROR(INDEX(Registro!$P$2:$P$500,MATCH(22,Registro!$T$2:$T$500,0)),"") | H23: =IFERROR(INDEX(Registro!$Q$2:$Q$500,MATCH(22,Registro!$T$2:$T$500,0)),"")
A24: =IFERROR(INDEX(Registro!$E$2:$E$500,MATCH(23,Registro!$T$2:$T$500,0)),"") | B24: =IFERROR(INDEX(Registro!$F$2:$F$500,MATCH(23,Registro!$T$2:$T$500,0)),"") | C24: =IFERROR(INDEX(Registro!$G$2:$G$500,MATCH(23,Registro!$T$2:$T$500,0)),"") | D24: =IFERROR(INDEX(Registro!$H$2:$H$500,MATCH(23,Registro!$T$2:$T$500,0)),"") | E24: =IFERROR(INDEX(Registro!$C$2:$C$500,MATCH(23,Registro!$T$2:$T$500,0)),"") | F24: =IFERROR(INDEX(Registro!$B$2:$B$500,MATCH(23,Registro!$T$2:$T$500,0)),"") | G24: =IFERROR(INDEX(Registro!$P$2:$P$500,MATCH(23,Registro!$T$2:$T$500,0)),"") | H24: =IFERROR(INDEX(Registro!$Q$2:$Q$500,MATCH(23,Registro!$T$2:$T$500,0)),"")
A25: =IFERROR(INDEX(Registro!$E$2:$E$500,MATCH(24,Registro!$T$2:$T$500,0)),"") | B25: =IFERROR(INDEX(Registro!$F$2:$F$500,MATCH(24,Registro!$T$2:$T$500,0)),"") | C25: =IFERROR(INDEX(Registro!$G$2:$G$500,MATCH(24,Registro!$T$2:$T$500,0)),"") | D25: =IFERROR(INDEX(Registro!$H$2:$H$500,MATCH(24,Registro!$T$2:$T$500,0)),"") | E25: =IFERROR(INDEX(Registro!$C$2:$C$500,MATCH(24,Registro!$T$2:$T$500,0)),"") | F25: =IFERROR(INDEX(Registro!$B$2:$B$500,MATCH(24,Registro!$T$2:$T$500,0)),"") | G25: =IFERROR(INDEX(Registro!$P$2:$P$500,MATCH(24,Registro!$T$2:$T$500,0)),"") | H25: =IFERROR(INDEX(Registro!$Q$2:$Q$500,MATCH(24,Registro!$T$2:$T$500,0)),"")
A26: =IFERROR(INDEX(Registro!$E$2:$E$500,MATCH(25,Registro!$T$2:$T$500,0)),"") | B26: =IFERROR(INDEX(Registro!$F$2:$F$500,MATCH(25,Registro!$T$2:$T$500,0)),"") | C26: =IFERROR(INDEX(Registro!$G$2:$G$500,MATCH(25,Registro!$T$2:$T$500,0)),"") | D26: =IFERROR(INDEX(Registro!$H$2:$H$500,MATCH(25,Registro!$T$2:$T$500,0)),"") | E26: =IFERROR(INDEX(Registro!$C$2:$C$500,MATCH(25,Registro!$T$2:$T$500,0)),"") | F26: =IFERROR(INDEX(Registro!$B$2:$B$500,MATCH(25,Registro!$T$2:$T$500,0)),"") | G26: =IFERROR(INDEX(Registro!$P$2:$P$500,MATCH(25,Registro!$T$2:$T$500,0)),"") | H26: =IFERROR(INDEX(Registro!$Q$2:$Q$500,MATCH(25,Registro!$T$2:$T$500,0)),"")
A27: =IFERROR(INDEX(Registro!$E$2:$E$500,MATCH(26,Registro!$T$2:$T$500,0)),"") | B27: =IFERROR(INDEX(Registro!$F$2:$F$500,MATCH(26,Registro!$T$2:$T$500,0)),"") | C27: =IFERROR(INDEX(Registro!$G$2:$G$500,MATCH(26,Registro!$T$2:$T$500,0)),"") | D27: =IFERROR(INDEX(Registro!$H$2:$H$500,MATCH(26,Registro!$T$2:$T$500,0)),"") | E27: =IFERROR(INDEX(Registro!$C$2:$C$500,MATCH(26,Registro!$T$2:$T$500,0)),"") | F27: =IFERROR(INDEX(Registro!$B$2:$B$500,MATCH(26,Registro!$T$2:$T$500,0)),"") | G27: =IFERROR(INDEX(Registro!$P$2:$P$500,MATCH(26,Registro!$T$2:$T$500,0)),"") | H27: =IFERROR(INDEX(Registro!$Q$2:$Q$500,MATCH(26,Registro!$T$2:$T$500,0)),"")
A28: =IFERROR(INDEX(Registro!$E$2:$E$500,MATCH(27,Registro!$T$2:$T$500,0)),"") | B28: =IFERROR(INDEX(Registro!$F$2:$F$500,MATCH(27,Registro!$T$2:$T$500,0)),"") | C28: =IFERROR(INDEX(Registro!$G$2:$G$500,MATCH(27,Registro!$T$2:$T$500,0)),"") | D28: =IFERROR(INDEX(Registro!$H$2:$H$500,MATCH(27,Registro!$T$2:$T$500,0)),"") | E28: =IFERROR(INDEX(Registro!$C$2:$C$500,MATCH(27,Registro!$T$2:$T$500,0)),"") | F28: =IFERROR(INDEX(Registro!$B$2:$B$500,MATCH(27,Registro!$T$2:$T$500,0)),"") | G28: =IFERROR(INDEX(Registro!$P$2:$P$500,MATCH(27,Registro!$T$2:$T$500,0)),"") | H28: =IFERROR(INDEX(Registro!$Q$2:$Q$500,MATCH(27,Registro!$T$2:$T$500,0)),"")
A29: =IFERROR(INDEX(Registro!$E$2:$E$500,MATCH(28,Registro!$T$2:$T$500,0)),"") | B29: =IFERROR(INDEX(Registro!$F$2:$F$500,MATCH(28,Registro!$T$2:$T$500,0)),"") | C29: =IFERROR(INDEX(Registro!$G$2:$G$500,MATCH(28,Registro!$T$2:$T$500,0)),"") | D29: =IFERROR(INDEX(Registro!$H$2:$H$500,MATCH(28,Registro!$T$2:$T$500,0)),"") | E29: =IFERROR(INDEX(Registro!$C$2:$C$500,MATCH(28,Registro!$T$2:$T$500,0)),"") | F29: =IFERROR(INDEX(Registro!$B$2:$B$500,MATCH(28,Registro!$T$2:$T$500,0)),"") | G29: =IFERROR(INDEX(Registro!$P$2:$P$500,MATCH(28,Registro!$T$2:$T$500,0)),"") | H29: =IFERROR(INDEX(Registro!$Q$2:$Q$500,MATCH(28,Registro!$T$2:$T$500,0)),"")
A30: =IFERROR(INDEX(Registro!$E$2:$E$500,MATCH(29,Registro!$T$2:$T$500,0)),"") | B30: =IFERROR(INDEX(Registro!$F$2:$F$500,MATCH(29,Registro!$T$2:$T$500,0)),"") | C30: =IFERROR(INDEX(Registro!$G$2:$G$500,MATCH(29,Registro!$T$2:$T$500,0)),"") | D30: =IFERROR(INDEX(Registro!$H$2:$H$500,MATCH(29,Registro!$T$2:$T$500,0)),"") | E30: =IFERROR(INDEX(Registro!$C$2:$C$500,MATCH(29,Registro!$T$2:$T$500,0)),"") | F30: =IFERROR(INDEX(Registro!$B$2:$B$500,MATCH(29,Registro!$T$2:$T$500,0)),"") | G30: =IFERROR(INDEX(Registro!$P$2:$P$500,MATCH(29,Registro!$T$2:$T$500,0)),"") | H30: =IFERROR(INDEX(Registro!$Q$2:$Q$500,MATCH(29,Registro!$T$2:$T$500,0)),"")
A31: =IFERROR(INDEX(Registro!$E$2:$E$500,MATCH(30,Registro!$T$2:$T$500,0)),"") | B31: =IFERROR(INDEX(Registro!$F$2:$F$500,MATCH(30,Registro!$T$2:$T$500,0)),"") | C31: =IFERROR(INDEX(Registro!$G$2:$G$500,MATCH(30,Registro!$T$2:$T$500,0)),"") | D31: =IFERROR(INDEX(Registro!$H$2:$H$500,MATCH(30,Registro!$T$2:$T$500,0)),"") | E31: =IFERROR(INDEX(Registro!$C$2:$C$500,MATCH(30,Registro!$T$2:$T$500,0)),"") | F31: =IFERROR(INDEX(Registro!$B$2:$B$500,MATCH(30,Registro!$T$2:$T$500,0)),"") | G31: =IFERROR(INDEX(Registro!$P$2:$P$500,MATCH(30,Registro!$T$2:$T$500,0)),"") | H31: =IFERROR(INDEX(Registro!$Q$2:$Q$500,MATCH(30,Registro!$T$2:$T$500,0)),"")
A32: =IFERROR(INDEX(Registro!$E$2:$E$500,MATCH(31,Registro!$T$2:$T$500,0)),"") | B32: =IFERROR(INDEX(Registro!$F$2:$F$500,MATCH(31,Registro!$T$2:$T$500,0)),"") | C32: =IFERROR(INDEX(Registro!$G$2:$G$500,MATCH(31,Registro!$T$2:$T$500,0)),"") | D32: =IFERROR(INDEX(Registro!$H$2:$H$500,MATCH(31,Registro!$T$2:$T$500,0)),"") | E32: =IFERROR(INDEX(Registro!$C$2:$C$500,MATCH(31,Registro!$T$2:$T$500,0)),"") | F32: =IFERROR(INDEX(Registro!$B$2:$B$500,MATCH(31,Registro!$T$2:$T$500,0)),"") | G32: =IFERROR(INDEX(Registro!$P$2:$P$500,MATCH(31,Registro!$T$2:$T$500,0)),"") | H32: =IFERROR(INDEX(Registro!$Q$2:$Q$500,MATCH(31,Registro!$T$2:$T$500,0)),"")
A33: =IFERROR(INDEX(Registro!$E$2:$E$500,MATCH(32,Registro!$T$2:$T$500,0)),"") | B33: =IFERROR(INDEX(Registro!$F$2:$F$500,MATCH(32,Registro!$T$2:$T$500,0)),"") | C33: =IFERROR(INDEX(Registro!$G$2:$G$500,MATCH(32,Registro!$T$2:$T$500,0)),"") | D33: =IFERROR(INDEX(Registro!$H$2:$H$500,MATCH(32,Registro!$T$2:$T$500,0)),"") | E33: =IFERROR(INDEX(Registro!$C$2:$C$500,MATCH(32,Registro!$T$2:$T$500,0)),"") | F33: =IFERROR(INDEX(Registro!$B$2:$B$500,MATCH(32,Registro!$T$2:$T$500,0)),"") | G33: =IFERROR(INDEX(Registro!$P$2:$P$500,MATCH(32,Registro!$T$2:$T$500,0)),"") | H33: =IFERROR(INDEX(Registro!$Q$2:$Q$500,MATCH(32,Registro!$T$2:$T$500,0)),"")
A34: =IFERROR(INDEX(Registro!$E$2:$E$500,MATCH(33,Registro!$T$2:$T$500,0)),"") | B34: =IFERROR(INDEX(Registro!$F$2:$F$500,MATCH(33,Registro!$T$2:$T$500,0)),"") | C34: =IFERROR(INDEX(Registro!$G$2:$G$500,MATCH(33,Registro!$T$2:$T$500,0)),"") | D34: =IFERROR(INDEX(Registro!$H$2:$H$500,MATCH(33,Registro!$T$2:$T$500,0)),"") | E34: =IFERROR(INDEX(Registro!$C$2:$C$500,MATCH(33,Registro!$T$2:$T$500,0)),"") | F34: =IFERROR(INDEX(Registro!$B$2:$B$500,MATCH(33,Registro!$T$2:$T$500,0)),"") | G34: =IFERROR(INDEX(Registro!$P$2:$P$500,MATCH(33,Registro!$T$2:$T$500,0)),"") | H34: =IFERROR(INDEX(Registro!$Q$2:$Q$500,MATCH(33,Registro!$T$2:$T$500,0)),"")
A35: =IFERROR(INDEX(Registro!$E$2:$E$500,MATCH(34,Registro!$T$2:$T$500,0)),"") | B35: =IFERROR(INDEX(Registro!$F$2:$F$500,MATCH(34,Registro!$T$2:$T$500,0)),"") | C35: =IFERROR(INDEX(Registro!$G$2:$G$500,MATCH(34,Registro!$T$2:$T$500,0)),"") | D35: =IFERROR(INDEX(Registro!$H$2:$H$500,MATCH(34,Registro!$T$2:$T$500,0)),"") | E35: =IFERROR(INDEX(Registro!$C$2:$C$500,MATCH(34,Registro!$T$2:$T$500,0)),"") | F35: =IFERROR(INDEX(Registro!$B$2:$B$500,MATCH(34,Registro!$T$2:$T$500,0)),"") | G35: =IFERROR(INDEX(Registro!$P$2:$P$500,MATCH(34,Registro!$T$2:$T$500,0)),"") | H35: =IFERROR(INDEX(Registro!$Q$2:$Q$500,MATCH(34,Registro!$T$2:$T$500,0)),"")
A36: =IFERROR(INDEX(Registro!$E$2:$E$500,MATCH(35,Registro!$T$2:$T$500,0)),"") | B36: =IFERROR(INDEX(Registro!$F$2:$F$500,MATCH(35,Registro!$T$2:$T$500,0)),"") | C36: =IFERROR(INDEX(Registro!$G$2:$G$500,MATCH(35,Registro!$T$2:$T$500,0)),"") | D36: =IFERROR(INDEX(Registro!$H$2:$H$500,MATCH(35,Registro!$T$2:$T$500,0)),"") | E36: =IFERROR(INDEX(Registro!$C$2:$C$500,MATCH(35,Registro!$T$2:$T$500,0)),"") | F36: =IFERROR(INDEX(Registro!$B$2:$B$500,MATCH(35,Registro!$T$2:$T$500,0)),"") | G36: =IFERROR(INDEX(Registro!$P$2:$P$500,MATCH(35,Registro!$T$2:$T$500,0)),"") | H36: =IFERROR(INDEX(Registro!$Q$2:$Q$500,MATCH(35,Registro!$T$2:$T$500,0)),"")
A37: =IFERROR(INDEX(Registro!$E$2:$E$500,MATCH(36,Registro!$T$2:$T$500,0)),"") | B37: =IFERROR(INDEX(Registro!$F$2:$F$500,MATCH(36,Registro!$T$2:$T$500,0)),"") | C37: =IFERROR(INDEX(Registro!$G$2:$G$500,MATCH(36,Registro!$T$2:$T$500,0)),"") | D37: =IFERROR(INDEX(Registro!$H$2:$H$500,MATCH(36,Registro!$T$2:$T$500,0)),"") | E37: =IFERROR(INDEX(Registro!$C$2:$C$500,MATCH(36,Registro!$T$2:$T$500,0)),"") | F37: =IFERROR(INDEX(Registro!$B$2:$B$500,MATCH(36,Registro!$T$2:$T$500,0)),"") | G37: =IFERROR(INDEX(Registro!$P$2:$P$500,MATCH(36,Registro!$T$2:$T$500,0)),"") | H37: =IFERROR(INDEX(Registro!$Q$2:$Q$500,MATCH(36,Registro!$T$2:$T$500,0)),"")
A38: =IFERROR(INDEX(Registro!$E$2:$E$500,MATCH(37,Registro!$T$2:$T$500,0)),"") | B38: =IFERROR(INDEX(Registro!$F$2:$F$500,MATCH(37,Registro!$T$2:$T$500,0)),"") | C38: =IFERROR(INDEX(Registro!$G$2:$G$500,MATCH(37,Registro!$T$2:$T$500,0)),"") | D38: =IFERROR(INDEX(Registro!$H$2:$H$500,MATCH(37,Registro!$T$2:$T$500,0)),"") | E38: =IFERROR(INDEX(Registro!$C$2:$C$500,MATCH(37,Registro!$T$2:$T$500,0)),"") | F38: =IFERROR(INDEX(Registro!$B$2:$B$500,MATCH(37,Registro!$T$2:$T$500,0)),"") | G38: =IFERROR(INDEX(Registro!$P$2:$P$500,MATCH(37,Registro!$T$2:$T$500,0)),"") | H38: =IFERROR(INDEX(Registro!$Q$2:$Q$500,MATCH(37,Registro!$T$2:$T$500,0)),"")
A39: =IFERROR(INDEX(Registro!$E$2:$E$500,MATCH(38,Registro!$T$2:$T$500,0)),"") | B39: =IFERROR(INDEX(Registro!$F$2:$F$500,MATCH(38,Registro!$T$2:$T$500,0)),"") | C39: =IFERROR(INDEX(Registro!$G$2:$G$500,MATCH(38,Registro!$T$2:$T$500,0)),"") | D39: =IFERROR(INDEX(Registro!$H$2:$H$500,MATCH(38,Registro!$T$2:$T$500,0)),"") | E39: =IFERROR(INDEX(Registro!$C$2:$C$500,MATCH(38,Registro!$T$2:$T$500,0)),"") | F39: =IFERROR(INDEX(Registro!$B$2:$B$500,MATCH(38,Registro!$T$2:$T$500,0)),"") | G39: =IFERROR(INDEX(Registro!$P$2:$P$500,MATCH(38,Registro!$T$2:$T$500,0)),"") | H39: =IFERROR(INDEX(Registro!$Q$2:$Q$500,MATCH(38,Registro!$T$2:$T$500,0)),"")
A40: =IFERROR(INDEX(Registro!$E$2:$E$500,MATCH(39,Registro!$T$2:$T$500,0)),"") | B40: =IFERROR(INDEX(Registro!$F$2:$F$500,MATCH(39,Registro!$T$2:$T$500,0)),"") | C40: =IFERROR(INDEX(Registro!$G$2:$G$500,MATCH(39,Registro!$T$2:$T$500,0)),"") | D40: =IFERROR(INDEX(Registro!$H$2:$H$500,MATCH(39,Registro!$T$2:$T$500,0)),"") | E40: =IFERROR(INDEX(Registro!$C$2:$C$500,MATCH(39,Registro!$T$2:$T$500,0)),"") | F40: =IFERROR(INDEX(Registro!$B$2:$B$500,MATCH(39,Registro!$T$2:$T$500,0)),"") | G40: =IFERROR(INDEX(Registro!$P$2:$P$500,MATCH(39,Registro!$T$2:$T$500,0)),"") | H40: =IFERROR(INDEX(Registro!$Q$2:$Q$500,MATCH(39,Registro!$T$2:$T$500,0)),"")
...
