Workbook

Sheet Registro
A1: N° | B1: CAMPAÑA | C1: FECHA INGRESO | D1: CARGO | E1: No. DOCUMENTO | F1: NOMBRE COMPLETO | G1: TELÉFONO | H1: CORREO | I1: FORMADOR | J1: ASISTENCIA | K1: CONOCIMIENTO (1-5) | L1: HABILIDAD COMERCIAL (1-5) | M1: ACTITUD (1-5) | N1: PROMEDIO | O1: RESULTADO FORMACIÓN | P1: OBSERVACIONES | Q1: FECHA CIERRE | R1: RESPONSABLE CIERRE | S1: RESULTADO FINAL | T1: ORDEN APROBADOS
A2: =IF(E2="","",ROW()-1) | N2: =IF(COUNTA(K2:M2)=0,"",AVERAGE(K2:M2)) | T2: =IF(S2="Aprueba",COUNTIF($S$2:S2,"Aprueba"),"")
A3: =IF(E3="","",ROW()-1) | N3: =IF(COUNTA(K3:M3)=0,"",AVERAGE(K3:M3)) | T3: =IF(S3="Aprueba",COUNTIF($S$2:S3,"Aprueba"),"")
A4: =IF(E4="","",ROW()-1) | N4: =IF(COUNTA(K4:M4)=0,"",AVERAGE(K4:M4)) | T4: =IF(S4="Aprueba",COUNTIF($S$2:S4,"Aprueba"),"")
A5: =IF(E5="","",ROW()-1) | N5: =IF(COUNTA(K5:M5)=0,"",AVERAGE(K5:M5)) | T5: =IF(S5="Aprueba",COUNTIF($S$2:S5,"Aprueba"),"")
A6: =IF(E6="","",ROW()-1) | N6: =IF(COUNTA(K6:M6)=0,"",AVERAGE(K6:M6)) | T6: =IF(S6="Aprueba",COUNTIF($S$2:S6,"Aprueba"),"")
A7: =IF(E7="","",ROW()-1) | N7: =IF(COUNTA(K7:M7)=0,"",AVERAGE(K7:M7)) | T7: =IF(S7="Aprueba",COUNTIF($S$2:S7,"Aprueba"),"")
A8: =IF(E8="","",ROW()-1) | N8: =IF(COUNTA(K8:M8)=0,"",AVERAGE(K8:M8)) | T8: =IF(S8="Aprueba",COUNTIF($S$2:S8,"Aprueba"),"")
A9: =IF(E9="","",ROW()-1) | N9: =IF(COUNTA(K9:M9)=0,"",AVERAGE(K9:M9)) | T9: =IF(S9="Aprueba",COUNTIF($S$2:S9,"Aprueba"),"")
A10: =IF(E10="","",ROW()-1) | N10: =IF(COUNTA(K10:M10)=0,"",AVERAGE(K10:M10)) | T10: =IF(S10="Aprueba",COUNTIF($S$2:S10,"Aprueba"),"")
A11: =IF(E11="","",ROW()-1) | N11: =IF(COUNTA(K11:M11)=0,"",AVERAGE(K11:M11)) | T11: =IF(S11="Aprueba",COUNTIF($S$2:S11,"Aprueba"),"")
A12: =IF(E12="","",ROW()-1) | N12: =IF(COUNTA(K12:M12)=0,"",AVERAGE(K12:M12)) | T12: =IF(S12="Aprueba",COUNTIF($S$2:S12,"Aprueba"),"")
A13: =IF(E13="","",ROW()-1) | N13: =IF(COUNTA(K13:M13)=0,"",AVERAGE(K13:M13)) | T13: =IF(S13="Aprueba",COUNTIF($S$2:S13,"Aprueba"),"")
... A100: =IF(E100="","",ROW()-1) | N100: =IF(COUNTA(K100:M100)=0,"",AVERAGE(K100:M100)) | T100: =IF(S100="Aprueba",COUNTIF($S$2:S100,"Aprueba"),"")

Sheet Parametros
A1: PARÁMETROS — ONBOARDING ESCUELA COMERCIAL
A3: RESPUESTA | C3: RESULTADO REGISTRO | O3: DÍA
A4: Sí | C4: Aprueba | O4: 1
A5: No | C5: No aprueba | O5: 2
O6: 3
O7: 4
O8: 5
A10: INSTRUCCIONES DE USO
A11: 1. Registra a cada participante en la hoja Registro. 2. Selecciona 'Aprueba' en RESULTADO FINAL para enviarlo automáticamente a OJT. 3. Diligencia los cinco días de seguimiento en OJT. 4. Registra manualmente si PASA OJT en la tabla final. 5. Consulta los indicadores consolidados en Resumen.

Sheet Resumen
A1: RESUMEN — ONBOARDING ESCUELA COMERCIAL
A3: Indicadores automáticos de Registro y del seguimiento OJT.
A5: REGISTROS CREADOS | B5: =COUNTIF(Registro!$E$2:$E$100,"<>") -> 0 | D5: Flujo operativo Registro → aprobación final → seguimiento OJT de 5 días → decisión PASA OJT. Las métricas se actualizan al abrir el archivo en Excel y recalcular las fórmulas.
A6: APROBADOS EN REGISTRO | B6: =COUNTIF(Registro!$S$2:$S$100,"Aprueba") -> 0
A7: NO APROBADOS EN REGISTRO | B7: =COUNTIF(Registro!$S$2:$S$100,"No aprueba") -> 0
A8: PARTICIPANTES EN OJT | B8: =SUMPRODUCT((OJT!$B$158:$B$187<>"")*1) -> 1
A9: PASA OJT | B9: =COUNTIF(OJT!$I$158:$I$187,"Sí") -> 0
A10: NO PASA OJT | B10: =COUNTIF(OJT!$I$158:$I$187,"No") -> 0
A11: PENDIENTES DE DECISIÓN OJT | B11: =MAX(B8-B9-B10,0) -> 1

Sheet OJT
A1: SEGUIMIENTO OJT — ESCUELA COMERCIAL (5 DÍAS x PERSONA)
A2: Solo ingresan aquí quienes obtuvieron 'Aprueba' en la hoja Registro. Cada persona ocupa 5 filas (una por día); elige el día en el desplegable de la columna DÍA.
A4: N° | B4: No. DOCUMENTO | C4: NOMBRE COMPLETO | D4: CAMPAÑA | E4: FORMADOR | F4: DÍA | G4: FECHA | H4: MATRÍCULAS | I4: ADERECIA | J4: ACTITUD (1-5) | K4: OBSERVACIONES
A5: =IFERROR(IF(INDEX(Registro!$E$2:$E$100,MATCH(1,Registro!$T$2:$T$100,0))="","",1),"") | B5: =SI.ERROR(INDICE(Registro!$E$2:$E$100;COINCIDIR(1;Registro!$T$2:$T$100;0));"") | C5: =IFERROR(INDEX(Registro!$F$2:$F$100,MATCH(1,Registro!$T$2:$T$100,0)),"") | D5: =IFERROR(INDEX(Registro!$B$2:$B$100,MATCH(1,Registro!$T$2:$T$100,0)),"") | E5: =IFERROR(INDEX(Registro!$I$2:$I$100,MATCH(1,Registro!$T$2:$T$100,0)),"") | F5: 1
F6: 2
F7: 3
F8: 4
F9: 5
A10: =IFERROR(IF(INDEX(Registro!$E$2:$E$100,MATCH(2,Registro!$T$2:$T$100,0))="","",2),"") | B10: =IFERROR(INDEX(Registro!$E$2:$E$100,MATCH(2,Registro!$T$2:$T$100,0)),"") | C10: =IFERROR(INDEX(Registro!$F$2:$F$100,MATCH(2,Registro!$T$2:$T$100,0)),"") | D10: =IFERROR(INDEX(Registro!$B$2:$B$100,MATCH(2,Registro!$T$2:$T$100,0)),"") | E10: =IFERROR(INDEX(Registro!$I$2:$I$100,MATCH(2,Registro!$T$2:$T$100,0)),"") | F10: 1
F11: 2
F12: 3
F13: 4
F14: 5
A15: =IFERROR(IF(INDEX(Registro!$E$2:$E$100,MATCH(3,Registro!$T$2:$T$100,0))="","",3),"") | B15: =IFERROR(INDEX(Registro!$E$2:$E$100,MATCH(3,Registro!$T$2:$T$100,0)),"") | C15: =IFERROR(INDEX(Registro!$F$2:$F$100,MATCH(3,Registro!$T$2:$T$100,0)),"") | D15: =IFERROR(INDEX(Registro!$B$2:$B$100,MATCH(3,Registro!$T$2:$T$100,0)),"") | E15: =IFERROR(INDEX(Registro!$I$2:$I$100,MATCH(3,Registro!$T$2:$T$100,0)),"") | F15: 1
F16: 2
F17: 3
F18: 4
F19: 5
A20: =IFERROR(IF(INDEX(Registro!$E$2:$E$100,MATCH(4,Registro!$T$2:$T$100,0))="","",4),"") | B20: =IFERROR(INDEX(Registro!$E$2:$E$100,MATCH(4,Registro!$T$2:$T$100,0)),"") | C20: =IFERROR(INDEX(Registro!$F$2:$F$100,MATCH(4,Registro!$T$2:$T$100,0)),"") | D20: =IFERROR(INDEX(Registro!$B$2:$B$100,MATCH(4,Registro!$T$2:$T$100,0)),"") | E20: =IFERROR(INDEX(Registro!$I$2:$I$100,MATCH(4,Registro!$T$2:$T$100,0)),"") | F20: 1
F21: 2
F22: 3
F23: 4
F24: 5
A25: =IFERROR(IF(INDEX(Registro!$E$2:$E$100,MATCH(5,Registro!$T$2:$T$100,0))="","",5),"") | B25: =IFERROR(INDEX(Registro!$E$2:$E$100,MATCH(5,Registro!$T$2:$T$100,0)),"") | C25: =IFERROR(INDEX(Registro!$F$2:$F$100,MATCH(5,Registro!$T$2:$T$100,0)),"") | D25: =IFERROR(INDEX(Registro!$B$2:$B$100,MATCH(5,Registro!$T$2:$T$100,0)),"") | E25: =IFERROR(INDEX(Registro!$I$2:$I$100,MATCH(5,Registro!$T$2:$T$100,0)),"") | F25: 1
F26: 2
F27: 3
F28: 4
F29: 5
A30: =IFERROR(IF(INDEX(Registro!$E$2:$E$100,MATCH(6,Registro!$T$2:$T$100,0))="","",6),"") | B30: =IFERROR(INDEX(Registro!$E$2:$E$100,MATCH(6,Registro!$T$2:$T$100,0)),"") | C30: =IFERROR(INDEX(Registro!$F$2:$F$100,MATCH(6,Registro!$T$2:$T$100,0)),"") | D30: =IFERROR(INDEX(Registro!$B$2:$B$100,MATCH(6,Registro!$T$2:$T$100,0)),"") | E30: =IFERROR(INDEX(Registro!$I$2:$I$100,MATCH(6,Registro!$T$2:$T$100,0)),"") | F30: 1
F31: 2
F32: 3
F33: 4
F34: 5
A35: =IFERROR(IF(INDEX(Registro!$E$2:$E$100,MATCH(7,Registro!$T$2:$T$100,0))="","",7),"") | B35: =IFERROR(INDEX(Registro!$E$2:$E$100,MATCH(7,Registro!$T$2:$T$100,0)),"") | C35: =IFERROR(INDEX(Registro!$F$2:$F$100,MATCH(7,Registro!$T$2:$T$100,0)),"") | D35: =IFERROR(INDEX(Registro!$B$2:$B$100,MATCH(7,Registro!$T$2:$T$100,0)),"") | E35: =IFERROR(INDEX(Registro!$I$2:$I$100,MATCH(7,Registro!$T$2:$T$100,0)),"") | F35: 1
F36: 2
F37: 3
F38: 4
F39: 5
A40: =IFERROR(IF(INDEX(Registro!$E$2:$E$100,MATCH(8,Registro!$T$2:$T$100,0))="","",8),"") | B40: =IFERROR(INDEX(Registro!$E$2:$E$100,MATCH(8,Registro!$T$2:$T$100,0)),"") | C40: =IFERROR(INDEX(Registro!$F$2:$F$100,MATCH(8,Registro!$T$2:$T$100,0)),"") | D40: =IFERROR(INDEX(Registro!$B$2:$B$100,MATCH(8,Registro!$T$2:$T$100,0)),"") | E40: =IFERROR(INDEX(Registro!$I$2:$I$100,MATCH(8,Registro!$T$2:$T$100,0)),"") | F40: 1
F41: 2
...
